Watching for file changes with StatReloader
Watching for file changes with StatReloader
Not Found: /favicon.ico
Watching for file changes with StatReloader
Not Found: /
Internal Server Error: /admin/GIRng/character/
Traceback (most recent call last):
  File "D:\Project\Django\.venv\lib\site-packages\django\db\backends\utils.py", line 89, in _execute
    return self.cursor.execute(sql, params)
  File "D:\Project\Django\.venv\lib\site-packages\django\db\backends\mysql\base.py", line 75, in execute
    return self.cursor.execute(query, args)
  File "D:\Project\Django\.venv\lib\site-packages\MySQLdb\cursors.py", line 206, in execute
    res = self._query(query)
  File "D:\Project\Django\.venv\lib\site-packages\MySQLdb\cursors.py", line 319, in _query
    db.query(q)
  File "D:\Project\Django\.venv\lib\site-packages\MySQLdb\connections.py", line 254, in query
    _mysql.connection.query(self, query)
MySQLdb.OperationalError: (1054, "Unknown column 'GIRng_character.description' in 'field list'")

The above exception was the direct cause of the following exception:

Traceback (most recent call last):
  File "D:\Project\Django\.venv\lib\site-packages\django\core\handlers\exception.py", line 55, in inner
    response = get_response(request)
  File "D:\Project\Django\.venv\lib\site-packages\django\core\handlers\base.py", line 197, in _get_response
    response = wrapped_callback(request, *callback_args, **callback_kwargs)
  File "D:\Project\Django\.venv\lib\site-packages\django\contrib\admin\options.py", line 686, in wrapper
    return self.admin_site.admin_view(view)(*args, **kwargs)
  File "D:\Project\Django\.venv\lib\site-packages\django\utils\decorators.py", line 133, in _wrapped_view
    response = view_func(request, *args, **kwargs)
  File "D:\Project\Django\.venv\lib\site-packages\django\views\decorators\cache.py", line 62, in _wrapped_view_func
    response = view_func(request, *args, **kwargs)
  File "D:\Project\Django\.venv\lib\site-packages\django\contrib\admin\sites.py", line 242, in inner
    return view(request, *args, **kwargs)
  File "D:\Project\Django\.venv\lib\site-packages\django\utils\decorators.py", line 46, in _wrapper
    return bound_method(*args, **kwargs)
  File "D:\Project\Django\.venv\lib\site-packages\django\utils\decorators.py", line 133, in _wrapped_view
    response = view_func(request, *args, **kwargs)
  File "D:\Project\Django\.venv\lib\site-packages\django\contrib\admin\options.py", line 2068, in changelist_view
    "selection_note": _("0 of %(cnt)s selected") % {"cnt": len(cl.result_list)},
  File "D:\Project\Django\.venv\lib\site-packages\django\db\models\query.py", line 376, in __len__
    self._fetch_all()
  File "D:\Project\Django\.venv\lib\site-packages\django\db\models\query.py", line 1867, in _fetch_all
    self._result_cache = list(self._iterable_class(self))
  File "D:\Project\Django\.venv\lib\site-packages\django\db\models\query.py", line 87, in __iter__
    results = compiler.execute_sql(
  File "D:\Project\Django\.venv\lib\site-packages\django\db\models\sql\compiler.py", line 1398, in execute_sql
    cursor.execute(sql, params)
  File "D:\Project\Django\.venv\lib\site-packages\django\db\backends\utils.py", line 103, in execute
    return super().execute(sql, params)
  File "D:\Project\Django\.venv\lib\site-packages\django\db\backends\utils.py", line 67, in execute
    return self._execute_with_wrappers(
  File "D:\Project\Django\.venv\lib\site-packages\django\db\backends\utils.py", line 80, in _execute_with_wrappers
    return executor(sql, params, many, context)
  File "D:\Project\Django\.venv\lib\site-packages\django\db\backends\utils.py", line 84, in _execute
    with self.db.wrap_database_errors:
  File "D:\Project\Django\.venv\lib\site-packages\django\db\utils.py", line 91, in __exit__
    raise dj_exc_value.with_traceback(traceback) from exc_value
  File "D:\Project\Django\.venv\lib\site-packages\django\db\backends\utils.py", line 89, in _execute
    return self.cursor.execute(sql, params)
  File "D:\Project\Django\.venv\lib\site-packages\django\db\backends\mysql\base.py", line 75, in execute
    return self.cursor.execute(query, args)
  File "D:\Project\Django\.venv\lib\site-packages\MySQLdb\cursors.py", line 206, in execute
    res = self._query(query)
  File "D:\Project\Django\.venv\lib\site-packages\MySQLdb\cursors.py", line 319, in _query
    db.query(q)
  File "D:\Project\Django\.venv\lib\site-packages\MySQLdb\connections.py", line 254, in query
    _mysql.connection.query(self, query)
django.db.utils.OperationalError: (1054, "Unknown column 'GIRng_character.description' in 'field list'")
Internal Server Error: /admin/GIRng/team/
Traceback (most recent call last):
  File "D:\Project\Django\.venv\lib\site-packages\django\db\backends\utils.py", line 89, in _execute
    return self.cursor.execute(sql, params)
  File "D:\Project\Django\.venv\lib\site-packages\django\db\backends\mysql\base.py", line 75, in execute
    return self.cursor.execute(query, args)
  File "D:\Project\Django\.venv\lib\site-packages\MySQLdb\cursors.py", line 206, in execute
    res = self._query(query)
  File "D:\Project\Django\.venv\lib\site-packages\MySQLdb\cursors.py", line 319, in _query
    db.query(q)
  File "D:\Project\Django\.venv\lib\site-packages\MySQLdb\connections.py", line 254, in query
    _mysql.connection.query(self, query)
MySQLdb.OperationalError: (1054, "Unknown column 'GIRng_team.description' in 'field list'")

The above exception was the direct cause of the following exception:

Traceback (most recent call last):
  File "D:\Project\Django\.venv\lib\site-packages\django\core\handlers\exception.py", line 55, in inner
    response = get_response(request)
  File "D:\Project\Django\.venv\lib\site-packages\django\core\handlers\base.py", line 197, in _get_response
    response = wrapped_callback(request, *callback_args, **callback_kwargs)
  File "D:\Project\Django\.venv\lib\site-packages\django\contrib\admin\options.py", line 686, in wrapper
    return self.admin_site.admin_view(view)(*args, **kwargs)
  File "D:\Project\Django\.venv\lib\site-packages\django\utils\decorators.py", line 133, in _wrapped_view
    response = view_func(request, *args, **kwargs)
  File "D:\Project\Django\.venv\lib\site-packages\django\views\decorators\cache.py", line 62, in _wrapped_view_func
    response = view_func(request, *args, **kwargs)
  File "D:\Project\Django\.venv\lib\site-packages\django\contrib\admin\sites.py", line 242, in inner
    return view(request, *args, **kwargs)
  File "D:\Project\Django\.venv\lib\site-packages\django\utils\decorators.py", line 46, in _wrapper
    return bound_method(*args, **kwargs)
  File "D:\Project\Django\.venv\lib\site-packages\django\utils\decorators.py", line 133, in _wrapped_view
    response = view_func(request, *args, **kwargs)
  File "D:\Project\Django\.venv\lib\site-packages\django\contrib\admin\options.py", line 2068, in changelist_view
    "selection_note": _("0 of %(cnt)s selected") % {"cnt": len(cl.result_list)},
  File "D:\Project\Django\.venv\lib\site-packages\django\db\models\query.py", line 376, in __len__
    self._fetch_all()
  File "D:\Project\Django\.venv\lib\site-packages\django\db\models\query.py", line 1867, in _fetch_all
    self._result_cache = list(self._iterable_class(self))
  File "D:\Project\Django\.venv\lib\site-packages\django\db\models\query.py", line 87, in __iter__
    results = compiler.execute_sql(
  File "D:\Project\Django\.venv\lib\site-packages\django\db\models\sql\compiler.py", line 1398, in execute_sql
    cursor.execute(sql, params)
  File "D:\Project\Django\.venv\lib\site-packages\django\db\backends\utils.py", line 103, in execute
    return super().execute(sql, params)
  File "D:\Project\Django\.venv\lib\site-packages\django\db\backends\utils.py", line 67, in execute
    return self._execute_with_wrappers(
  File "D:\Project\Django\.venv\lib\site-packages\django\db\backends\utils.py", line 80, in _execute_with_wrappers
    return executor(sql, params, many, context)
  File "D:\Project\Django\.venv\lib\site-packages\django\db\backends\utils.py", line 84, in _execute
    with self.db.wrap_database_errors:
  File "D:\Project\Django\.venv\lib\site-packages\django\db\utils.py", line 91, in __exit__
    raise dj_exc_value.with_traceback(traceback) from exc_value
  File "D:\Project\Django\.venv\lib\site-packages\django\db\backends\utils.py", line 89, in _execute
    return self.cursor.execute(sql, params)
  File "D:\Project\Django\.venv\lib\site-packages\django\db\backends\mysql\base.py", line 75, in execute
    return self.cursor.execute(query, args)
  File "D:\Project\Django\.venv\lib\site-packages\MySQLdb\cursors.py", line 206, in execute
    res = self._query(query)
  File "D:\Project\Django\.venv\lib\site-packages\MySQLdb\cursors.py", line 319, in _query
    db.query(q)
  File "D:\Project\Django\.venv\lib\site-packages\MySQLdb\connections.py", line 254, in query
    _mysql.connection.query(self, query)
django.db.utils.OperationalError: (1054, "Unknown column 'GIRng_team.description' in 'field list'")
D:\Project\Django\mysite\GIRng\models.py changed, reloading.
Watching for file changes with StatReloader
Watching for file changes with StatReloader
Watching for file changes with StatReloader
Not Found: /favicon.ico
Internal Server Error: /admin/GIRng/character/
Traceback (most recent call last):
  File "D:\Project\Django\.venv\lib\site-packages\django\db\backends\utils.py", line 89, in _execute
    return self.cursor.execute(sql, params)
  File "D:\Project\Django\.venv\lib\site-packages\django\db\backends\mysql\base.py", line 75, in execute
    return self.cursor.execute(query, args)
  File "D:\Project\Django\.venv\lib\site-packages\MySQLdb\cursors.py", line 206, in execute
    res = self._query(query)
  File "D:\Project\Django\.venv\lib\site-packages\MySQLdb\cursors.py", line 319, in _query
    db.query(q)
  File "D:\Project\Django\.venv\lib\site-packages\MySQLdb\connections.py", line 254, in query
    _mysql.connection.query(self, query)
MySQLdb.OperationalError: (1054, "Unknown column 'GIRng_character.level' in 'field list'")

The above exception was the direct cause of the following exception:

Traceback (most recent call last):
  File "D:\Project\Django\.venv\lib\site-packages\django\core\handlers\exception.py", line 55, in inner
    response = get_response(request)
  File "D:\Project\Django\.venv\lib\site-packages\django\core\handlers\base.py", line 197, in _get_response
    response = wrapped_callback(request, *callback_args, **callback_kwargs)
  File "D:\Project\Django\.venv\lib\site-packages\django\contrib\admin\options.py", line 686, in wrapper
    return self.admin_site.admin_view(view)(*args, **kwargs)
  File "D:\Project\Django\.venv\lib\site-packages\django\utils\decorators.py", line 133, in _wrapped_view
    response = view_func(request, *args, **kwargs)
  File "D:\Project\Django\.venv\lib\site-packages\django\views\decorators\cache.py", line 62, in _wrapped_view_func
    response = view_func(request, *args, **kwargs)
  File "D:\Project\Django\.venv\lib\site-packages\django\contrib\admin\sites.py", line 242, in inner
    return view(request, *args, **kwargs)
  File "D:\Project\Django\.venv\lib\site-packages\django\utils\decorators.py", line 46, in _wrapper
    return bound_method(*args, **kwargs)
  File "D:\Project\Django\.venv\lib\site-packages\django\utils\decorators.py", line 133, in _wrapped_view
    response = view_func(request, *args, **kwargs)
  File "D:\Project\Django\.venv\lib\site-packages\django\contrib\admin\options.py", line 2068, in changelist_view
    "selection_note": _("0 of %(cnt)s selected") % {"cnt": len(cl.result_list)},
  File "D:\Project\Django\.venv\lib\site-packages\django\db\models\query.py", line 376, in __len__
    self._fetch_all()
  File "D:\Project\Django\.venv\lib\site-packages\django\db\models\query.py", line 1867, in _fetch_all
    self._result_cache = list(self._iterable_class(self))
  File "D:\Project\Django\.venv\lib\site-packages\django\db\models\query.py", line 87, in __iter__
    results = compiler.execute_sql(
  File "D:\Project\Django\.venv\lib\site-packages\django\db\models\sql\compiler.py", line 1398, in execute_sql
    cursor.execute(sql, params)
  File "D:\Project\Django\.venv\lib\site-packages\django\db\backends\utils.py", line 103, in execute
    return super().execute(sql, params)
  File "D:\Project\Django\.venv\lib\site-packages\django\db\backends\utils.py", line 67, in execute
    return self._execute_with_wrappers(
  File "D:\Project\Django\.venv\lib\site-packages\django\db\backends\utils.py", line 80, in _execute_with_wrappers
    return executor(sql, params, many, context)
  File "D:\Project\Django\.venv\lib\site-packages\django\db\backends\utils.py", line 84, in _execute
    with self.db.wrap_database_errors:
  File "D:\Project\Django\.venv\lib\site-packages\django\db\utils.py", line 91, in __exit__
    raise dj_exc_value.with_traceback(traceback) from exc_value
  File "D:\Project\Django\.venv\lib\site-packages\django\db\backends\utils.py", line 89, in _execute
    return self.cursor.execute(sql, params)
  File "D:\Project\Django\.venv\lib\site-packages\django\db\backends\mysql\base.py", line 75, in execute
    return self.cursor.execute(query, args)
  File "D:\Project\Django\.venv\lib\site-packages\MySQLdb\cursors.py", line 206, in execute
    res = self._query(query)
  File "D:\Project\Django\.venv\lib\site-packages\MySQLdb\cursors.py", line 319, in _query
    db.query(q)
  File "D:\Project\Django\.venv\lib\site-packages\MySQLdb\connections.py", line 254, in query
    _mysql.connection.query(self, query)
django.db.utils.OperationalError: (1054, "Unknown column 'GIRng_character.level' in 'field list'")
D:\Project\Django\mysite\GIRng\models.py changed, reloading.
Watching for file changes with StatReloader
Watching for file changes with StatReloader
Not Found: /account
Not Found: /accounts/
Internal Server Error: /accounts/login/
Traceback (most recent call last):
  File "D:\Project\Django\.venv\lib\site-packages\django\core\handlers\exception.py", line 55, in inner
    response = get_response(request)
  File "D:\Project\Django\.venv\lib\site-packages\django\core\handlers\base.py", line 220, in _get_response
    response = response.render()
  File "D:\Project\Django\.venv\lib\site-packages\django\template\response.py", line 114, in render
    self.content = self.rendered_content
  File "D:\Project\Django\.venv\lib\site-packages\django\template\response.py", line 90, in rendered_content
    template = self.resolve_template(self.template_name)
  File "D:\Project\Django\.venv\lib\site-packages\django\template\response.py", line 72, in resolve_template
    return select_template(template, using=self.using)
  File "D:\Project\Django\.venv\lib\site-packages\django\template\loader.py", line 47, in select_template
    raise TemplateDoesNotExist(", ".join(template_name_list), chain=chain)
django.template.exceptions.TemplateDoesNotExist: registration/login.html
D:\Project\Django\mysite\GIRng\views.py changed, reloading.
Watching for file changes with StatReloader
Not Found: /accounts/
Internal Server Error: /accounts/login/
Traceback (most recent call last):
  File "D:\Project\Django\.venv\lib\site-packages\django\core\handlers\exception.py", line 55, in inner
    response = get_response(request)
  File "D:\Project\Django\.venv\lib\site-packages\django\core\handlers\base.py", line 220, in _get_response
    response = response.render()
  File "D:\Project\Django\.venv\lib\site-packages\django\template\response.py", line 114, in render
    self.content = self.rendered_content
  File "D:\Project\Django\.venv\lib\site-packages\django\template\response.py", line 90, in rendered_content
    template = self.resolve_template(self.template_name)
  File "D:\Project\Django\.venv\lib\site-packages\django\template\response.py", line 72, in resolve_template
    return select_template(template, using=self.using)
  File "D:\Project\Django\.venv\lib\site-packages\django\template\loader.py", line 47, in select_template
    raise TemplateDoesNotExist(", ".join(template_name_list), chain=chain)
django.template.exceptions.TemplateDoesNotExist: registration/login.html
Internal Server Error: /accounts/login/
Traceback (most recent call last):
  File "D:\Project\Django\.venv\lib\site-packages\django\core\handlers\exception.py", line 55, in inner
    response = get_response(request)
  File "D:\Project\Django\.venv\lib\site-packages\django\core\handlers\base.py", line 220, in _get_response
    response = response.render()
  File "D:\Project\Django\.venv\lib\site-packages\django\template\response.py", line 114, in render
    self.content = self.rendered_content
  File "D:\Project\Django\.venv\lib\site-packages\django\template\response.py", line 90, in rendered_content
    template = self.resolve_template(self.template_name)
  File "D:\Project\Django\.venv\lib\site-packages\django\template\response.py", line 72, in resolve_template
    return select_template(template, using=self.using)
  File "D:\Project\Django\.venv\lib\site-packages\django\template\loader.py", line 47, in select_template
    raise TemplateDoesNotExist(", ".join(template_name_list), chain=chain)
django.template.exceptions.TemplateDoesNotExist: registration/login.html
D:\Project\Django\mysite\GIRng\views.py changed, reloading.
Watching for file changes with StatReloader
Internal Server Error: /accounts/login/
Traceback (most recent call last):
  File "D:\Project\Django\.venv\lib\site-packages\django\core\handlers\exception.py", line 55, in inner
    response = get_response(request)
  File "D:\Project\Django\.venv\lib\site-packages\django\core\handlers\base.py", line 220, in _get_response
    response = response.render()
  File "D:\Project\Django\.venv\lib\site-packages\django\template\response.py", line 114, in render
    self.content = self.rendered_content
  File "D:\Project\Django\.venv\lib\site-packages\django\template\response.py", line 90, in rendered_content
    template = self.resolve_template(self.template_name)
  File "D:\Project\Django\.venv\lib\site-packages\django\template\response.py", line 72, in resolve_template
    return select_template(template, using=self.using)
  File "D:\Project\Django\.venv\lib\site-packages\django\template\loader.py", line 47, in select_template
    raise TemplateDoesNotExist(", ".join(template_name_list), chain=chain)
django.template.exceptions.TemplateDoesNotExist: registration/login.html
Internal Server Error: /accounts/login/
Traceback (most recent call last):
  File "D:\Project\Django\.venv\lib\site-packages\django\core\handlers\exception.py", line 55, in inner
    response = get_response(request)
  File "D:\Project\Django\.venv\lib\site-packages\django\core\handlers\base.py", line 220, in _get_response
    response = response.render()
  File "D:\Project\Django\.venv\lib\site-packages\django\template\response.py", line 114, in render
    self.content = self.rendered_content
  File "D:\Project\Django\.venv\lib\site-packages\django\template\response.py", line 90, in rendered_content
    template = self.resolve_template(self.template_name)
  File "D:\Project\Django\.venv\lib\site-packages\django\template\response.py", line 72, in resolve_template
    return select_template(template, using=self.using)
  File "D:\Project\Django\.venv\lib\site-packages\django\template\loader.py", line 47, in select_template
    raise TemplateDoesNotExist(", ".join(template_name_list), chain=chain)
django.template.exceptions.TemplateDoesNotExist: registration/login.html
D:\Project\Django\mysite\GIRng\views.py changed, reloading.
Watching for file changes with StatReloader
Internal Server Error: /accounts/login/
Traceback (most recent call last):
  File "D:\Project\Django\.venv\lib\site-packages\django\core\handlers\exception.py", line 55, in inner
    response = get_response(request)
  File "D:\Project\Django\.venv\lib\site-packages\django\core\handlers\base.py", line 220, in _get_response
    response = response.render()
  File "D:\Project\Django\.venv\lib\site-packages\django\template\response.py", line 114, in render
    self.content = self.rendered_content
  File "D:\Project\Django\.venv\lib\site-packages\django\template\response.py", line 90, in rendered_content
    template = self.resolve_template(self.template_name)
  File "D:\Project\Django\.venv\lib\site-packages\django\template\response.py", line 72, in resolve_template
    return select_template(template, using=self.using)
  File "D:\Project\Django\.venv\lib\site-packages\django\template\loader.py", line 47, in select_template
    raise TemplateDoesNotExist(", ".join(template_name_list), chain=chain)
django.template.exceptions.TemplateDoesNotExist: registration/login.html
Internal Server Error: /accounts/login/
Traceback (most recent call last):
  File "D:\Project\Django\.venv\lib\site-packages\django\core\handlers\exception.py", line 55, in inner
    response = get_response(request)
  File "D:\Project\Django\.venv\lib\site-packages\django\core\handlers\base.py", line 220, in _get_response
    response = response.render()
  File "D:\Project\Django\.venv\lib\site-packages\django\template\response.py", line 114, in render
    self.content = self.rendered_content
  File "D:\Project\Django\.venv\lib\site-packages\django\template\response.py", line 90, in rendered_content
    template = self.resolve_template(self.template_name)
  File "D:\Project\Django\.venv\lib\site-packages\django\template\response.py", line 72, in resolve_template
    return select_template(template, using=self.using)
  File "D:\Project\Django\.venv\lib\site-packages\django\template\loader.py", line 47, in select_template
    raise TemplateDoesNotExist(", ".join(template_name_list), chain=chain)
django.template.exceptions.TemplateDoesNotExist: registration/login.html
Watching for file changes with StatReloader
Internal Server Error: /accounts/login/
Traceback (most recent call last):
  File "D:\Project\Django\.venv\lib\site-packages\django\core\handlers\exception.py", line 55, in inner
    response = get_response(request)
  File "D:\Project\Django\.venv\lib\site-packages\django\core\handlers\base.py", line 220, in _get_response
    response = response.render()
  File "D:\Project\Django\.venv\lib\site-packages\django\template\response.py", line 114, in render
    self.content = self.rendered_content
  File "D:\Project\Django\.venv\lib\site-packages\django\template\response.py", line 90, in rendered_content
    template = self.resolve_template(self.template_name)
  File "D:\Project\Django\.venv\lib\site-packages\django\template\response.py", line 72, in resolve_template
    return select_template(template, using=self.using)
  File "D:\Project\Django\.venv\lib\site-packages\django\template\loader.py", line 47, in select_template
    raise TemplateDoesNotExist(", ".join(template_name_list), chain=chain)
django.template.exceptions.TemplateDoesNotExist: registration/login.html
D:\Project\Django\mysite\GIRng\views.py changed, reloading.
Watching for file changes with StatReloader
D:\Project\Django\mysite\mysite\urls.py changed, reloading.
Watching for file changes with StatReloader
D:\Project\Django\mysite\GIRng\urls.py changed, reloading.
Watching for file changes with StatReloader
Not Found: /girng/account/login
Internal Server Error: /girng/accounts/login/
Traceback (most recent call last):
  File "D:\Project\Django\.venv\lib\site-packages\django\core\handlers\exception.py", line 55, in inner
    response = get_response(request)
  File "D:\Project\Django\.venv\lib\site-packages\django\core\handlers\base.py", line 220, in _get_response
    response = response.render()
  File "D:\Project\Django\.venv\lib\site-packages\django\template\response.py", line 114, in render
    self.content = self.rendered_content
  File "D:\Project\Django\.venv\lib\site-packages\django\template\response.py", line 92, in rendered_content
    return template.render(context, self._request)
  File "D:\Project\Django\.venv\lib\site-packages\django\template\backends\django.py", line 62, in render
    return self.template.render(context)
  File "D:\Project\Django\.venv\lib\site-packages\django\template\base.py", line 175, in render
    return self._render(context)
  File "D:\Project\Django\.venv\lib\site-packages\django\template\base.py", line 167, in _render
    return self.nodelist.render(context)
  File "D:\Project\Django\.venv\lib\site-packages\django\template\base.py", line 1005, in render
    return SafeString("".join([node.render_annotated(context) for node in self]))
  File "D:\Project\Django\.venv\lib\site-packages\django\template\base.py", line 1005, in <listcomp>
    return SafeString("".join([node.render_annotated(context) for node in self]))
  File "D:\Project\Django\.venv\lib\site-packages\django\template\base.py", line 966, in render_annotated
    return self.render(context)
  File "D:\Project\Django\.venv\lib\site-packages\django\template\defaulttags.py", line 472, in render
    url = reverse(view_name, args=args, kwargs=kwargs, current_app=current_app)
  File "D:\Project\Django\.venv\lib\site-packages\django\urls\base.py", line 88, in reverse
    return resolver._reverse_with_prefix(view, prefix, *args, **kwargs)
  File "D:\Project\Django\.venv\lib\site-packages\django\urls\resolvers.py", line 828, in _reverse_with_prefix
    raise NoReverseMatch(msg)
django.urls.exceptions.NoReverseMatch: Reverse for 'login' not found. 'login' is not a valid view function or pattern name.
Forbidden (CSRF token missing.): /girng/accounts/login/
Not Found: /accounts/profile/
D:\Project\Django\mysite\GIRng\views.py changed, reloading.
Watching for file changes with StatReloader
D:\Project\Django\mysite\GIRng\views.py changed, reloading.
Watching for file changes with StatReloader
Internal Server Error: /girng/accounts/login/
Traceback (most recent call last):
  File "D:\Project\Django\.venv\lib\site-packages\django\core\handlers\exception.py", line 55, in inner
    response = get_response(request)
  File "D:\Project\Django\.venv\lib\site-packages\django\core\handlers\base.py", line 220, in _get_response
    response = response.render()
  File "D:\Project\Django\.venv\lib\site-packages\django\template\response.py", line 114, in render
    self.content = self.rendered_content
  File "D:\Project\Django\.venv\lib\site-packages\django\template\response.py", line 92, in rendered_content
    return template.render(context, self._request)
  File "D:\Project\Django\.venv\lib\site-packages\django\template\backends\django.py", line 62, in render
    return self.template.render(context)
  File "D:\Project\Django\.venv\lib\site-packages\django\template\base.py", line 175, in render
    return self._render(context)
  File "D:\Project\Django\.venv\lib\site-packages\django\template\base.py", line 167, in _render
    return self.nodelist.render(context)
  File "D:\Project\Django\.venv\lib\site-packages\django\template\base.py", line 1005, in render
    return SafeString("".join([node.render_annotated(context) for node in self]))
  File "D:\Project\Django\.venv\lib\site-packages\django\template\base.py", line 1005, in <listcomp>
    return SafeString("".join([node.render_annotated(context) for node in self]))
  File "D:\Project\Django\.venv\lib\site-packages\django\template\base.py", line 966, in render_annotated
    return self.render(context)
  File "D:\Project\Django\.venv\lib\site-packages\django\template\loader_tags.py", line 54, in render
    result = self.nodelist.render(context)
  File "D:\Project\Django\.venv\lib\site-packages\django\template\base.py", line 1005, in render
    return SafeString("".join([node.render_annotated(context) for node in self]))
  File "D:\Project\Django\.venv\lib\site-packages\django\template\base.py", line 1005, in <listcomp>
    return SafeString("".join([node.render_annotated(context) for node in self]))
  File "D:\Project\Django\.venv\lib\site-packages\django\template\base.py", line 966, in render_annotated
    return self.render(context)
  File "D:\Project\Django\.venv\lib\site-packages\django\template\defaulttags.py", line 472, in render
    url = reverse(view_name, args=args, kwargs=kwargs, current_app=current_app)
  File "D:\Project\Django\.venv\lib\site-packages\django\urls\base.py", line 88, in reverse
    return resolver._reverse_with_prefix(view, prefix, *args, **kwargs)
  File "D:\Project\Django\.venv\lib\site-packages\django\urls\resolvers.py", line 828, in _reverse_with_prefix
    raise NoReverseMatch(msg)
django.urls.exceptions.NoReverseMatch: Reverse for 'login' not found. 'login' is not a valid view function or pattern name.
Internal Server Error: /girng/accounts/login/
Traceback (most recent call last):
  File "D:\Project\Django\.venv\lib\site-packages\django\core\handlers\exception.py", line 55, in inner
    response = get_response(request)
  File "D:\Project\Django\.venv\lib\site-packages\django\core\handlers\base.py", line 220, in _get_response
    response = response.render()
  File "D:\Project\Django\.venv\lib\site-packages\django\template\response.py", line 114, in render
    self.content = self.rendered_content
  File "D:\Project\Django\.venv\lib\site-packages\django\template\response.py", line 92, in rendered_content
    return template.render(context, self._request)
  File "D:\Project\Django\.venv\lib\site-packages\django\template\backends\django.py", line 62, in render
    return self.template.render(context)
  File "D:\Project\Django\.venv\lib\site-packages\django\template\base.py", line 175, in render
    return self._render(context)
  File "D:\Project\Django\.venv\lib\site-packages\django\template\base.py", line 167, in _render
    return self.nodelist.render(context)
  File "D:\Project\Django\.venv\lib\site-packages\django\template\base.py", line 1005, in render
    return SafeString("".join([node.render_annotated(context) for node in self]))
  File "D:\Project\Django\.venv\lib\site-packages\django\template\base.py", line 1005, in <listcomp>
    return SafeString("".join([node.render_annotated(context) for node in self]))
  File "D:\Project\Django\.venv\lib\site-packages\django\template\base.py", line 966, in render_annotated
    return self.render(context)
  File "D:\Project\Django\.venv\lib\site-packages\django\template\loader_tags.py", line 54, in render
    result = self.nodelist.render(context)
  File "D:\Project\Django\.venv\lib\site-packages\django\template\base.py", line 1005, in render
    return SafeString("".join([node.render_annotated(context) for node in self]))
  File "D:\Project\Django\.venv\lib\site-packages\django\template\base.py", line 1005, in <listcomp>
    return SafeString("".join([node.render_annotated(context) for node in self]))
  File "D:\Project\Django\.venv\lib\site-packages\django\template\base.py", line 966, in render_annotated
    return self.render(context)
  File "D:\Project\Django\.venv\lib\site-packages\django\template\defaulttags.py", line 472, in render
    url = reverse(view_name, args=args, kwargs=kwargs, current_app=current_app)
  File "D:\Project\Django\.venv\lib\site-packages\django\urls\base.py", line 88, in reverse
    return resolver._reverse_with_prefix(view, prefix, *args, **kwargs)
  File "D:\Project\Django\.venv\lib\site-packages\django\urls\resolvers.py", line 828, in _reverse_with_prefix
    raise NoReverseMatch(msg)
django.urls.exceptions.NoReverseMatch: Reverse for 'password_reset' not found. 'password_reset' is not a valid view function or pattern name.
Not Found: /accounts/profile/
D:\Project\Django\mysite\GIRng\views.py changed, reloading.
Watching for file changes with StatReloader
This is logger: xdding
D:\Project\Django\mysite\GIRng\views.py changed, reloading.
Watching for file changes with StatReloader
Watching for file changes with StatReloader
D:\Project\Django\mysite\GIRng\views.py changed, reloading.
Watching for file changes with StatReloader
Not Found: /girng/account/login
D:\Project\Django\mysite\GIRng\views.py changed, reloading.
Watching for file changes with StatReloader
This is logger: xdding
D:\Project\Django\mysite\GIRng\views.py changed, reloading.
Watching for file changes with StatReloader
This is logger: xdding
D:\Project\Django\mysite\GIRng\views.py changed, reloading.
Watching for file changes with StatReloader
This is logger: xdding
This is logger: xdding
D:\Project\Django\mysite\GIRng\views.py changed, reloading.
Watching for file changes with StatReloader
This is logger: xdding
This is logger: xdding
D:\Project\Django\mysite\GIRng\views.py changed, reloading.
Watching for file changes with StatReloader
D:\Project\Django\mysite\GIRng\views.py changed, reloading.
Watching for file changes with StatReloader
This is logger: xdding
D:\Project\Django\mysite\GIRng\views.py changed, reloading.
Watching for file changes with StatReloader
This is logger: xdding
D:\Project\Django\mysite\GIRng\views.py changed, reloading.
Watching for file changes with StatReloader
This is logger: xdding
Internal Server Error: /girng/
Traceback (most recent call last):
  File "D:\Project\Django\.venv\lib\site-packages\django\core\handlers\exception.py", line 55, in inner
    response = get_response(request)
  File "D:\Project\Django\.venv\lib\site-packages\django\core\handlers\base.py", line 197, in _get_response
    response = wrapped_callback(request, *callback_args, **callback_kwargs)
  File "D:\Project\Django\mysite\GIRng\views.py", line 26, in index
    return render(request, 'GIRng/.html')
  File "D:\Project\Django\.venv\lib\site-packages\django\shortcuts.py", line 24, in render
    content = loader.render_to_string(template_name, context, request, using=using)
  File "D:\Project\Django\.venv\lib\site-packages\django\template\loader.py", line 61, in render_to_string
    template = get_template(template_name, using=using)
  File "D:\Project\Django\.venv\lib\site-packages\django\template\loader.py", line 19, in get_template
    raise TemplateDoesNotExist(template_name, chain=chain)
django.template.exceptions.TemplateDoesNotExist: GIRng/.html
D:\Project\Django\mysite\GIRng\views.py changed, reloading.
Watching for file changes with StatReloader
This is logger: xdding
D:\Project\Django\mysite\GIRng\views.py changed, reloading.
Watching for file changes with StatReloader
This is logger: xdding
Not Found: /favicon.ico
This is logger: xdding
Not Found: /favicon.ico
This is logger: xdding
D:\Project\Django\mysite\GIRng\views.py changed, reloading.
Watching for file changes with StatReloader
D:\Project\Django\mysite\GIRng\views.py changed, reloading.
Watching for file changes with StatReloader
This is logger: xdding
D:\Project\Django\mysite\GIRng\views.py changed, reloading.
Watching for file changes with StatReloader
This is logger: xdding
This is logger: xdding
This is logger: xdding
D:\Project\Django\mysite\GIRng\views.py changed, reloading.
Watching for file changes with StatReloader
D:\Project\Django\mysite\GIRng\views.py changed, reloading.
Watching for file changes with StatReloader
This is logger: xdding
D:\Project\Django\mysite\GIRng\views.py changed, reloading.
Watching for file changes with StatReloader
This is logger: xdding
Watching for file changes with StatReloader
This is logger: xdding
This is logger: xdding
Not Found: /accounts/login/
D:\Project\Django\mysite\GIRng\views.py changed, reloading.
Watching for file changes with StatReloader
Not Found: /accounts/login/
Not Found: /girng/girng/accounts/login/
D:\Project\Django\mysite\GIRng\views.py changed, reloading.
Watching for file changes with StatReloader
D:\Project\Django\mysite\GIRng\views.py changed, reloading.
Watching for file changes with StatReloader
This is logger: xdding
Watching for file changes with StatReloader
This is logger: xdding
Internal Server Error: /girng/
Traceback (most recent call last):
  File "D:\Project\Django\.venv\lib\site-packages\django\core\handlers\exception.py", line 55, in inner
    response = get_response(request)
  File "D:\Project\Django\.venv\lib\site-packages\django\core\handlers\base.py", line 197, in _get_response
    response = wrapped_callback(request, *callback_args, **callback_kwargs)
  File "D:\Project\Django\.venv\lib\site-packages\django\contrib\auth\decorators.py", line 23, in _wrapped_view
    return view_func(request, *args, **kwargs)
  File "D:\Project\Django\mysite\GIRng\views.py", line 27, in index
    return render(request, 'GIRng/index.html')
  File "D:\Project\Django\.venv\lib\site-packages\django\shortcuts.py", line 24, in render
    content = loader.render_to_string(template_name, context, request, using=using)
  File "D:\Project\Django\.venv\lib\site-packages\django\template\loader.py", line 62, in render_to_string
    return template.render(context, request)
  File "D:\Project\Django\.venv\lib\site-packages\django\template\backends\django.py", line 62, in render
    return self.template.render(context)
  File "D:\Project\Django\.venv\lib\site-packages\django\template\base.py", line 175, in render
    return self._render(context)
  File "D:\Project\Django\.venv\lib\site-packages\django\template\base.py", line 167, in _render
    return self.nodelist.render(context)
  File "D:\Project\Django\.venv\lib\site-packages\django\template\base.py", line 1005, in render
    return SafeString("".join([node.render_annotated(context) for node in self]))
  File "D:\Project\Django\.venv\lib\site-packages\django\template\base.py", line 1005, in <listcomp>
    return SafeString("".join([node.render_annotated(context) for node in self]))
  File "D:\Project\Django\.venv\lib\site-packages\django\template\base.py", line 966, in render_annotated
    return self.render(context)
  File "D:\Project\Django\.venv\lib\site-packages\django\template\library.py", line 237, in render
    output = self.func(*resolved_args, **resolved_kwargs)
  File "D:\Project\Django\.venv\lib\site-packages\bootstrap5\templatetags\bootstrap5.py", line 319, in bootstrap_form
    return render_form(*args, **kwargs)
  File "D:\Project\Django\.venv\lib\site-packages\bootstrap5\forms.py", line 27, in render_form
    return renderer_cls(form, **kwargs).render()
  File "D:\Project\Django\.venv\lib\site-packages\bootstrap5\renderers.py", line 144, in __init__
    raise BootstrapError('Parameter "form" should contain a valid Django Form.')
bootstrap5.exceptions.BootstrapError: Parameter "form" should contain a valid Django Form.
Not Found: /favicon.ico
This is logger: xdding
Watching for file changes with StatReloader
This is logger: xdding
Internal Server Error: /girng/team
Traceback (most recent call last):
  File "D:\Project\Django\.venv\lib\site-packages\django\template\backends\django.py", line 62, in render
    return self.template.render(context)
  File "D:\Project\Django\.venv\lib\site-packages\django\template\base.py", line 175, in render
    return self._render(context)
  File "D:\Project\Django\.venv\lib\site-packages\django\template\base.py", line 167, in _render
    return self.nodelist.render(context)
  File "D:\Project\Django\.venv\lib\site-packages\django\template\base.py", line 1005, in render
    return SafeString("".join([node.render_annotated(context) for node in self]))
  File "D:\Project\Django\.venv\lib\site-packages\django\template\base.py", line 1005, in <listcomp>
    return SafeString("".join([node.render_annotated(context) for node in self]))
  File "D:\Project\Django\.venv\lib\site-packages\django\template\base.py", line 966, in render_annotated
    return self.render(context)
  File "D:\Project\Django\.venv\lib\site-packages\django\template\loader_tags.py", line 197, in render
    template = context.template.engine.select_template(template_name)
  File "D:\Project\Django\.venv\lib\site-packages\django\template\engine.py", line 212, in select_template
    raise TemplateDoesNotExist(", ".join(not_found))
django.template.exceptions.TemplateDoesNotExist: bootstrap5/field_help_text_and_errors.html

The above exception was the direct cause of the following exception:

Traceback (most recent call last):
  File "D:\Project\Django\.venv\lib\site-packages\django\core\handlers\exception.py", line 55, in inner
    response = get_response(request)
  File "D:\Project\Django\.venv\lib\site-packages\django\core\handlers\base.py", line 197, in _get_response
    response = wrapped_callback(request, *callback_args, **callback_kwargs)
  File "D:\Project\Django\mysite\GIRng\views.py", line 48, in team
    return render(request, 'GIRng/team.html', {'form': form})
  File "D:\Project\Django\.venv\lib\site-packages\django\shortcuts.py", line 24, in render
    content = loader.render_to_string(template_name, context, request, using=using)
  File "D:\Project\Django\.venv\lib\site-packages\django\template\loader.py", line 62, in render_to_string
    return template.render(context, request)
  File "D:\Project\Django\.venv\lib\site-packages\django\template\backends\django.py", line 64, in render
    reraise(exc, self.backend)
  File "D:\Project\Django\.venv\lib\site-packages\django\template\backends\django.py", line 85, in reraise
    raise new from exc
django.template.exceptions.TemplateDoesNotExist: bootstrap5/field_help_text_and_errors.html
Internal Server Error: /girng/team
Traceback (most recent call last):
  File "D:\Project\Django\.venv\lib\site-packages\django\template\backends\django.py", line 62, in render
    return self.template.render(context)
  File "D:\Project\Django\.venv\lib\site-packages\django\template\base.py", line 175, in render
    return self._render(context)
  File "D:\Project\Django\.venv\lib\site-packages\django\template\base.py", line 167, in _render
    return self.nodelist.render(context)
  File "D:\Project\Django\.venv\lib\site-packages\django\template\base.py", line 1005, in render
    return SafeString("".join([node.render_annotated(context) for node in self]))
  File "D:\Project\Django\.venv\lib\site-packages\django\template\base.py", line 1005, in <listcomp>
    return SafeString("".join([node.render_annotated(context) for node in self]))
  File "D:\Project\Django\.venv\lib\site-packages\django\template\base.py", line 966, in render_annotated
    return self.render(context)
  File "D:\Project\Django\.venv\lib\site-packages\django\template\loader_tags.py", line 197, in render
    template = context.template.engine.select_template(template_name)
  File "D:\Project\Django\.venv\lib\site-packages\django\template\engine.py", line 212, in select_template
    raise TemplateDoesNotExist(", ".join(not_found))
django.template.exceptions.TemplateDoesNotExist: bootstrap5/field_help_text_and_errors.html

The above exception was the direct cause of the following exception:

Traceback (most recent call last):
  File "D:\Project\Django\.venv\lib\site-packages\django\core\handlers\exception.py", line 55, in inner
    response = get_response(request)
  File "D:\Project\Django\.venv\lib\site-packages\django\core\handlers\base.py", line 197, in _get_response
    response = wrapped_callback(request, *callback_args, **callback_kwargs)
  File "D:\Project\Django\mysite\GIRng\views.py", line 48, in team
    return render(request, 'GIRng/team.html', {'form': form})
  File "D:\Project\Django\.venv\lib\site-packages\django\shortcuts.py", line 24, in render
    content = loader.render_to_string(template_name, context, request, using=using)
  File "D:\Project\Django\.venv\lib\site-packages\django\template\loader.py", line 62, in render_to_string
    return template.render(context, request)
  File "D:\Project\Django\.venv\lib\site-packages\django\template\backends\django.py", line 64, in render
    reraise(exc, self.backend)
  File "D:\Project\Django\.venv\lib\site-packages\django\template\backends\django.py", line 85, in reraise
    raise new from exc
django.template.exceptions.TemplateDoesNotExist: bootstrap5/field_help_text_and_errors.html
D:\Project\Django\mysite\mysite\settings.py changed, reloading.
Watching for file changes with StatReloader
Internal Server Error: /girng/team
Traceback (most recent call last):
  File "D:\Project\Django\.venv\lib\site-packages\django\template\backends\django.py", line 62, in render
    return self.template.render(context)
  File "D:\Project\Django\.venv\lib\site-packages\django\template\base.py", line 175, in render
    return self._render(context)
  File "D:\Project\Django\.venv\lib\site-packages\django\template\base.py", line 167, in _render
    return self.nodelist.render(context)
  File "D:\Project\Django\.venv\lib\site-packages\django\template\base.py", line 1005, in render
    return SafeString("".join([node.render_annotated(context) for node in self]))
  File "D:\Project\Django\.venv\lib\site-packages\django\template\base.py", line 1005, in <listcomp>
    return SafeString("".join([node.render_annotated(context) for node in self]))
  File "D:\Project\Django\.venv\lib\site-packages\django\template\base.py", line 966, in render_annotated
    return self.render(context)
  File "D:\Project\Django\.venv\lib\site-packages\django\template\loader_tags.py", line 197, in render
    template = context.template.engine.select_template(template_name)
  File "D:\Project\Django\.venv\lib\site-packages\django\template\engine.py", line 212, in select_template
    raise TemplateDoesNotExist(", ".join(not_found))
django.template.exceptions.TemplateDoesNotExist: bootstrap5/field_help_text_and_errors.html

The above exception was the direct cause of the following exception:

Traceback (most recent call last):
  File "D:\Project\Django\.venv\lib\site-packages\django\core\handlers\exception.py", line 55, in inner
    response = get_response(request)
  File "D:\Project\Django\.venv\lib\site-packages\django\core\handlers\base.py", line 197, in _get_response
    response = wrapped_callback(request, *callback_args, **callback_kwargs)
  File "D:\Project\Django\mysite\GIRng\views.py", line 48, in team
    return render(request, 'GIRng/team.html', {'form': form})
  File "D:\Project\Django\.venv\lib\site-packages\django\shortcuts.py", line 24, in render
    content = loader.render_to_string(template_name, context, request, using=using)
  File "D:\Project\Django\.venv\lib\site-packages\django\template\loader.py", line 62, in render_to_string
    return template.render(context, request)
  File "D:\Project\Django\.venv\lib\site-packages\django\template\backends\django.py", line 64, in render
    reraise(exc, self.backend)
  File "D:\Project\Django\.venv\lib\site-packages\django\template\backends\django.py", line 85, in reraise
    raise new from exc
django.template.exceptions.TemplateDoesNotExist: bootstrap5/field_help_text_and_errors.html
D:\Project\Django\mysite\mysite\settings.py changed, reloading.
Watching for file changes with StatReloader
Internal Server Error: /girng/team
Traceback (most recent call last):
  File "D:\Project\Django\.venv\lib\site-packages\django\template\backends\django.py", line 62, in render
    return self.template.render(context)
  File "D:\Project\Django\.venv\lib\site-packages\django\template\base.py", line 175, in render
    return self._render(context)
  File "D:\Project\Django\.venv\lib\site-packages\django\template\base.py", line 167, in _render
    return self.nodelist.render(context)
  File "D:\Project\Django\.venv\lib\site-packages\django\template\base.py", line 1005, in render
    return SafeString("".join([node.render_annotated(context) for node in self]))
  File "D:\Project\Django\.venv\lib\site-packages\django\template\base.py", line 1005, in <listcomp>
    return SafeString("".join([node.render_annotated(context) for node in self]))
  File "D:\Project\Django\.venv\lib\site-packages\django\template\base.py", line 966, in render_annotated
    return self.render(context)
  File "D:\Project\Django\.venv\lib\site-packages\django\template\loader_tags.py", line 197, in render
    template = context.template.engine.select_template(template_name)
  File "D:\Project\Django\.venv\lib\site-packages\django\template\engine.py", line 212, in select_template
    raise TemplateDoesNotExist(", ".join(not_found))
django.template.exceptions.TemplateDoesNotExist: bootstrap5/field_help_text_and_errors.html

The above exception was the direct cause of the following exception:

Traceback (most recent call last):
  File "D:\Project\Django\.venv\lib\site-packages\django\core\handlers\exception.py", line 55, in inner
    response = get_response(request)
  File "D:\Project\Django\.venv\lib\site-packages\django\core\handlers\base.py", line 197, in _get_response
    response = wrapped_callback(request, *callback_args, **callback_kwargs)
  File "D:\Project\Django\mysite\GIRng\views.py", line 48, in team
    return render(request, 'GIRng/team.html', {'form': form})
  File "D:\Project\Django\.venv\lib\site-packages\django\shortcuts.py", line 24, in render
    content = loader.render_to_string(template_name, context, request, using=using)
  File "D:\Project\Django\.venv\lib\site-packages\django\template\loader.py", line 62, in render_to_string
    return template.render(context, request)
  File "D:\Project\Django\.venv\lib\site-packages\django\template\backends\django.py", line 64, in render
    reraise(exc, self.backend)
  File "D:\Project\Django\.venv\lib\site-packages\django\template\backends\django.py", line 85, in reraise
    raise new from exc
django.template.exceptions.TemplateDoesNotExist: bootstrap5/field_help_text_and_errors.html
Internal Server Error: /girng/team
Traceback (most recent call last):
  File "D:\Project\Django\.venv\lib\site-packages\django\core\handlers\exception.py", line 55, in inner
    response = get_response(request)
  File "D:\Project\Django\.venv\lib\site-packages\django\core\handlers\base.py", line 197, in _get_response
    response = wrapped_callback(request, *callback_args, **callback_kwargs)
  File "D:\Project\Django\mysite\GIRng\views.py", line 48, in team
    return render(request, 'GIRng/team.html', {'form': form})
  File "D:\Project\Django\.venv\lib\site-packages\django\shortcuts.py", line 24, in render
    content = loader.render_to_string(template_name, context, request, using=using)
  File "D:\Project\Django\.venv\lib\site-packages\django\template\loader.py", line 61, in render_to_string
    template = get_template(template_name, using=using)
  File "D:\Project\Django\.venv\lib\site-packages\django\template\loader.py", line 15, in get_template
    return engine.get_template(template_name)
  File "D:\Project\Django\.venv\lib\site-packages\django\template\backends\django.py", line 34, in get_template
    return Template(self.engine.get_template(template_name), self)
  File "D:\Project\Django\.venv\lib\site-packages\django\template\engine.py", line 175, in get_template
    template, origin = self.find_template(template_name)
  File "D:\Project\Django\.venv\lib\site-packages\django\template\engine.py", line 157, in find_template
    template = loader.get_template(name, skip=skip)
  File "D:\Project\Django\.venv\lib\site-packages\django\template\loaders\cached.py", line 57, in get_template
    template = super().get_template(template_name, skip)
  File "D:\Project\Django\.venv\lib\site-packages\django\template\loaders\base.py", line 28, in get_template
    return Template(
  File "D:\Project\Django\.venv\lib\site-packages\django\template\base.py", line 154, in __init__
    self.nodelist = self.compile_nodelist()
  File "D:\Project\Django\.venv\lib\site-packages\django\template\base.py", line 200, in compile_nodelist
    return parser.parse()
  File "D:\Project\Django\.venv\lib\site-packages\django\template\base.py", line 513, in parse
    raise self.error(token, e)
  File "D:\Project\Django\.venv\lib\site-packages\django\template\base.py", line 511, in parse
    compiled_result = compile_func(self, token)
  File "D:\Project\Django\.venv\lib\site-packages\django\template\loader_tags.py", line 347, in do_include
    bits[1] = construct_relative_path(parser.origin.template_name, bits[1])
  File "D:\Project\Django\.venv\lib\site-packages\django\template\loader_tags.py", line 261, in construct_relative_path
    raise TemplateSyntaxError(
django.template.exceptions.TemplateSyntaxError: The relative path ''../../bootstrap5/field_help_text_and_errors.html'' points outside the file hierarchy that template 'GIRng/team.html' is in.
D:\Project\Django\mysite\mysite\settings.py changed, reloading.
Watching for file changes with StatReloader
D:\Project\Django\mysite\mysite\settings.py changed, reloading.
Watching for file changes with StatReloader
Internal Server Error: /girng/team
Traceback (most recent call last):
  File "D:\Project\Django\.venv\lib\site-packages\django\core\handlers\exception.py", line 55, in inner
    response = get_response(request)
  File "D:\Project\Django\.venv\lib\site-packages\django\core\handlers\base.py", line 197, in _get_response
    response = wrapped_callback(request, *callback_args, **callback_kwargs)
  File "D:\Project\Django\mysite\GIRng\views.py", line 48, in team
    return render(request, 'GIRng/team.html', {'form': form})
  File "D:\Project\Django\.venv\lib\site-packages\django\shortcuts.py", line 24, in render
    content = loader.render_to_string(template_name, context, request, using=using)
  File "D:\Project\Django\.venv\lib\site-packages\django\template\loader.py", line 61, in render_to_string
    template = get_template(template_name, using=using)
  File "D:\Project\Django\.venv\lib\site-packages\django\template\loader.py", line 15, in get_template
    return engine.get_template(template_name)
  File "D:\Project\Django\.venv\lib\site-packages\django\template\backends\django.py", line 34, in get_template
    return Template(self.engine.get_template(template_name), self)
  File "D:\Project\Django\.venv\lib\site-packages\django\template\engine.py", line 175, in get_template
    template, origin = self.find_template(template_name)
  File "D:\Project\Django\.venv\lib\site-packages\django\template\engine.py", line 157, in find_template
    template = loader.get_template(name, skip=skip)
  File "D:\Project\Django\.venv\lib\site-packages\django\template\loaders\cached.py", line 57, in get_template
    template = super().get_template(template_name, skip)
  File "D:\Project\Django\.venv\lib\site-packages\django\template\loaders\base.py", line 28, in get_template
    return Template(
  File "D:\Project\Django\.venv\lib\site-packages\django\template\base.py", line 154, in __init__
    self.nodelist = self.compile_nodelist()
  File "D:\Project\Django\.venv\lib\site-packages\django\template\base.py", line 200, in compile_nodelist
    return parser.parse()
  File "D:\Project\Django\.venv\lib\site-packages\django\template\base.py", line 513, in parse
    raise self.error(token, e)
  File "D:\Project\Django\.venv\lib\site-packages\django\template\base.py", line 511, in parse
    compiled_result = compile_func(self, token)
  File "D:\Project\Django\.venv\lib\site-packages\django\template\loader_tags.py", line 347, in do_include
    bits[1] = construct_relative_path(parser.origin.template_name, bits[1])
  File "D:\Project\Django\.venv\lib\site-packages\django\template\loader_tags.py", line 261, in construct_relative_path
    raise TemplateSyntaxError(
django.template.exceptions.TemplateSyntaxError: The relative path ''../../bootstrap5/field_help_text_and_errors.html'' points outside the file hierarchy that template 'GIRng/team.html' is in.
Internal Server Error: /girng/team
Traceback (most recent call last):
  File "D:\Project\Django\.venv\lib\site-packages\django\template\backends\django.py", line 62, in render
    return self.template.render(context)
  File "D:\Project\Django\.venv\lib\site-packages\django\template\base.py", line 175, in render
    return self._render(context)
  File "D:\Project\Django\.venv\lib\site-packages\django\template\base.py", line 167, in _render
    return self.nodelist.render(context)
  File "D:\Project\Django\.venv\lib\site-packages\django\template\base.py", line 1005, in render
    return SafeString("".join([node.render_annotated(context) for node in self]))
  File "D:\Project\Django\.venv\lib\site-packages\django\template\base.py", line 1005, in <listcomp>
    return SafeString("".join([node.render_annotated(context) for node in self]))
  File "D:\Project\Django\.venv\lib\site-packages\django\template\base.py", line 966, in render_annotated
    return self.render(context)
  File "D:\Project\Django\.venv\lib\site-packages\django\template\loader_tags.py", line 197, in render
    template = context.template.engine.select_template(template_name)
  File "D:\Project\Django\.venv\lib\site-packages\django\template\engine.py", line 212, in select_template
    raise TemplateDoesNotExist(", ".join(not_found))
django.template.exceptions.TemplateDoesNotExist: bootstrap5/field_help_text_and_errors.html

The above exception was the direct cause of the following exception:

Traceback (most recent call last):
  File "D:\Project\Django\.venv\lib\site-packages\django\core\handlers\exception.py", line 55, in inner
    response = get_response(request)
  File "D:\Project\Django\.venv\lib\site-packages\django\core\handlers\base.py", line 197, in _get_response
    response = wrapped_callback(request, *callback_args, **callback_kwargs)
  File "D:\Project\Django\mysite\GIRng\views.py", line 48, in team
    return render(request, 'GIRng/team.html', {'form': form})
  File "D:\Project\Django\.venv\lib\site-packages\django\shortcuts.py", line 24, in render
    content = loader.render_to_string(template_name, context, request, using=using)
  File "D:\Project\Django\.venv\lib\site-packages\django\template\loader.py", line 62, in render_to_string
    return template.render(context, request)
  File "D:\Project\Django\.venv\lib\site-packages\django\template\backends\django.py", line 64, in render
    reraise(exc, self.backend)
  File "D:\Project\Django\.venv\lib\site-packages\django\template\backends\django.py", line 85, in reraise
    raise new from exc
django.template.exceptions.TemplateDoesNotExist: bootstrap5/field_help_text_and_errors.html
D:\Project\Django\mysite\mysite\settings.py changed, reloading.
Watching for file changes with StatReloader
Internal Server Error: /girng/team
Traceback (most recent call last):
  File "D:\Project\Django\.venv\lib\site-packages\django\template\backends\django.py", line 62, in render
    return self.template.render(context)
  File "D:\Project\Django\.venv\lib\site-packages\django\template\base.py", line 175, in render
    return self._render(context)
  File "D:\Project\Django\.venv\lib\site-packages\django\template\base.py", line 167, in _render
    return self.nodelist.render(context)
  File "D:\Project\Django\.venv\lib\site-packages\django\template\base.py", line 1005, in render
    return SafeString("".join([node.render_annotated(context) for node in self]))
  File "D:\Project\Django\.venv\lib\site-packages\django\template\base.py", line 1005, in <listcomp>
    return SafeString("".join([node.render_annotated(context) for node in self]))
  File "D:\Project\Django\.venv\lib\site-packages\django\template\base.py", line 966, in render_annotated
    return self.render(context)
  File "D:\Project\Django\.venv\lib\site-packages\django\template\loader_tags.py", line 197, in render
    template = context.template.engine.select_template(template_name)
  File "D:\Project\Django\.venv\lib\site-packages\django\template\engine.py", line 212, in select_template
    raise TemplateDoesNotExist(", ".join(not_found))
django.template.exceptions.TemplateDoesNotExist: bootstrap5/field_help_text_and_errors.html

The above exception was the direct cause of the following exception:

Traceback (most recent call last):
  File "D:\Project\Django\.venv\lib\site-packages\django\core\handlers\exception.py", line 55, in inner
    response = get_response(request)
  File "D:\Project\Django\.venv\lib\site-packages\django\core\handlers\base.py", line 197, in _get_response
    response = wrapped_callback(request, *callback_args, **callback_kwargs)
  File "D:\Project\Django\mysite\GIRng\views.py", line 48, in team
    return render(request, 'GIRng/team.html', {'form': form})
  File "D:\Project\Django\.venv\lib\site-packages\django\shortcuts.py", line 24, in render
    content = loader.render_to_string(template_name, context, request, using=using)
  File "D:\Project\Django\.venv\lib\site-packages\django\template\loader.py", line 62, in render_to_string
    return template.render(context, request)
  File "D:\Project\Django\.venv\lib\site-packages\django\template\backends\django.py", line 64, in render
    reraise(exc, self.backend)
  File "D:\Project\Django\.venv\lib\site-packages\django\template\backends\django.py", line 85, in reraise
    raise new from exc
django.template.exceptions.TemplateDoesNotExist: bootstrap5/field_help_text_and_errors.html
D:\Project\Django\mysite\mysite\settings.py changed, reloading.
Watching for file changes with StatReloader
Internal Server Error: /girng/team
Traceback (most recent call last):
  File "D:\Project\Django\.venv\lib\site-packages\django\template\backends\django.py", line 62, in render
    return self.template.render(context)
  File "D:\Project\Django\.venv\lib\site-packages\django\template\base.py", line 175, in render
    return self._render(context)
  File "D:\Project\Django\.venv\lib\site-packages\django\template\base.py", line 167, in _render
    return self.nodelist.render(context)
  File "D:\Project\Django\.venv\lib\site-packages\django\template\base.py", line 1005, in render
    return SafeString("".join([node.render_annotated(context) for node in self]))
  File "D:\Project\Django\.venv\lib\site-packages\django\template\base.py", line 1005, in <listcomp>
    return SafeString("".join([node.render_annotated(context) for node in self]))
  File "D:\Project\Django\.venv\lib\site-packages\django\template\base.py", line 966, in render_annotated
    return self.render(context)
  File "D:\Project\Django\.venv\lib\site-packages\django\template\loader_tags.py", line 197, in render
    template = context.template.engine.select_template(template_name)
  File "D:\Project\Django\.venv\lib\site-packages\django\template\engine.py", line 212, in select_template
    raise TemplateDoesNotExist(", ".join(not_found))
django.template.exceptions.TemplateDoesNotExist: bootstrap5/field_help_text_and_errors.html

The above exception was the direct cause of the following exception:

Traceback (most recent call last):
  File "D:\Project\Django\.venv\lib\site-packages\django\core\handlers\exception.py", line 55, in inner
    response = get_response(request)
  File "D:\Project\Django\.venv\lib\site-packages\django\core\handlers\base.py", line 197, in _get_response
    response = wrapped_callback(request, *callback_args, **callback_kwargs)
  File "D:\Project\Django\mysite\GIRng\views.py", line 48, in team
    return render(request, 'GIRng/team.html', {'form': form})
  File "D:\Project\Django\.venv\lib\site-packages\django\shortcuts.py", line 24, in render
    content = loader.render_to_string(template_name, context, request, using=using)
  File "D:\Project\Django\.venv\lib\site-packages\django\template\loader.py", line 62, in render_to_string
    return template.render(context, request)
  File "D:\Project\Django\.venv\lib\site-packages\django\template\backends\django.py", line 64, in render
    reraise(exc, self.backend)
  File "D:\Project\Django\.venv\lib\site-packages\django\template\backends\django.py", line 85, in reraise
    raise new from exc
django.template.exceptions.TemplateDoesNotExist: bootstrap5/field_help_text_and_errors.html
D:\Project\Django\mysite\mysite\settings.py changed, reloading.
Watching for file changes with StatReloader
Internal Server Error: /girng/team
Traceback (most recent call last):
  File "D:\Project\Django\.venv\lib\site-packages\django\template\backends\django.py", line 62, in render
    return self.template.render(context)
  File "D:\Project\Django\.venv\lib\site-packages\django\template\base.py", line 175, in render
    return self._render(context)
  File "D:\Project\Django\.venv\lib\site-packages\django\template\base.py", line 167, in _render
    return self.nodelist.render(context)
  File "D:\Project\Django\.venv\lib\site-packages\django\template\base.py", line 1005, in render
    return SafeString("".join([node.render_annotated(context) for node in self]))
  File "D:\Project\Django\.venv\lib\site-packages\django\template\base.py", line 1005, in <listcomp>
    return SafeString("".join([node.render_annotated(context) for node in self]))
  File "D:\Project\Django\.venv\lib\site-packages\django\template\base.py", line 966, in render_annotated
    return self.render(context)
  File "D:\Project\Django\.venv\lib\site-packages\django\template\loader_tags.py", line 197, in render
    template = context.template.engine.select_template(template_name)
  File "D:\Project\Django\.venv\lib\site-packages\django\template\engine.py", line 212, in select_template
    raise TemplateDoesNotExist(", ".join(not_found))
django.template.exceptions.TemplateDoesNotExist: bootstrap5/field_help_text_and_errors.html

The above exception was the direct cause of the following exception:

Traceback (most recent call last):
  File "D:\Project\Django\.venv\lib\site-packages\django\core\handlers\exception.py", line 55, in inner
    response = get_response(request)
  File "D:\Project\Django\.venv\lib\site-packages\django\core\handlers\base.py", line 197, in _get_response
    response = wrapped_callback(request, *callback_args, **callback_kwargs)
  File "D:\Project\Django\mysite\GIRng\views.py", line 48, in team
    return render(request, 'GIRng/team.html', {'form': form})
  File "D:\Project\Django\.venv\lib\site-packages\django\shortcuts.py", line 24, in render
    content = loader.render_to_string(template_name, context, request, using=using)
  File "D:\Project\Django\.venv\lib\site-packages\django\template\loader.py", line 62, in render_to_string
    return template.render(context, request)
  File "D:\Project\Django\.venv\lib\site-packages\django\template\backends\django.py", line 64, in render
    reraise(exc, self.backend)
  File "D:\Project\Django\.venv\lib\site-packages\django\template\backends\django.py", line 85, in reraise
    raise new from exc
django.template.exceptions.TemplateDoesNotExist: bootstrap5/field_help_text_and_errors.html
Internal Server Error: /girng/team
Traceback (most recent call last):
  File "D:\Project\Django\.venv\lib\site-packages\django\template\backends\django.py", line 62, in render
    return self.template.render(context)
  File "D:\Project\Django\.venv\lib\site-packages\django\template\base.py", line 175, in render
    return self._render(context)
  File "D:\Project\Django\.venv\lib\site-packages\django\template\base.py", line 167, in _render
    return self.nodelist.render(context)
  File "D:\Project\Django\.venv\lib\site-packages\django\template\base.py", line 1005, in render
    return SafeString("".join([node.render_annotated(context) for node in self]))
  File "D:\Project\Django\.venv\lib\site-packages\django\template\base.py", line 1005, in <listcomp>
    return SafeString("".join([node.render_annotated(context) for node in self]))
  File "D:\Project\Django\.venv\lib\site-packages\django\template\base.py", line 966, in render_annotated
    return self.render(context)
  File "D:\Project\Django\.venv\lib\site-packages\django\template\loader_tags.py", line 197, in render
    template = context.template.engine.select_template(template_name)
  File "D:\Project\Django\.venv\lib\site-packages\django\template\engine.py", line 212, in select_template
    raise TemplateDoesNotExist(", ".join(not_found))
django.template.exceptions.TemplateDoesNotExist: field_help_text_and_errors.html

The above exception was the direct cause of the following exception:

Traceback (most recent call last):
  File "D:\Project\Django\.venv\lib\site-packages\django\core\handlers\exception.py", line 55, in inner
    response = get_response(request)
  File "D:\Project\Django\.venv\lib\site-packages\django\core\handlers\base.py", line 197, in _get_response
    response = wrapped_callback(request, *callback_args, **callback_kwargs)
  File "D:\Project\Django\mysite\GIRng\views.py", line 48, in team
    return render(request, 'GIRng/team.html', {'form': form})
  File "D:\Project\Django\.venv\lib\site-packages\django\shortcuts.py", line 24, in render
    content = loader.render_to_string(template_name, context, request, using=using)
  File "D:\Project\Django\.venv\lib\site-packages\django\template\loader.py", line 62, in render_to_string
    return template.render(context, request)
  File "D:\Project\Django\.venv\lib\site-packages\django\template\backends\django.py", line 64, in render
    reraise(exc, self.backend)
  File "D:\Project\Django\.venv\lib\site-packages\django\template\backends\django.py", line 85, in reraise
    raise new from exc
django.template.exceptions.TemplateDoesNotExist: field_help_text_and_errors.html
Internal Server Error: /girng/team
Traceback (most recent call last):
  File "D:\Project\Django\.venv\lib\site-packages\django\template\backends\django.py", line 62, in render
    return self.template.render(context)
  File "D:\Project\Django\.venv\lib\site-packages\django\template\base.py", line 175, in render
    return self._render(context)
  File "D:\Project\Django\.venv\lib\site-packages\django\template\base.py", line 167, in _render
    return self.nodelist.render(context)
  File "D:\Project\Django\.venv\lib\site-packages\django\template\base.py", line 1005, in render
    return SafeString("".join([node.render_annotated(context) for node in self]))
  File "D:\Project\Django\.venv\lib\site-packages\django\template\base.py", line 1005, in <listcomp>
    return SafeString("".join([node.render_annotated(context) for node in self]))
  File "D:\Project\Django\.venv\lib\site-packages\django\template\base.py", line 966, in render_annotated
    return self.render(context)
  File "D:\Project\Django\.venv\lib\site-packages\django\template\loader_tags.py", line 197, in render
    template = context.template.engine.select_template(template_name)
  File "D:\Project\Django\.venv\lib\site-packages\django\template\engine.py", line 212, in select_template
    raise TemplateDoesNotExist(", ".join(not_found))
django.template.exceptions.TemplateDoesNotExist: field_help_text_and_errors.html

The above exception was the direct cause of the following exception:

Traceback (most recent call last):
  File "D:\Project\Django\.venv\lib\site-packages\django\core\handlers\exception.py", line 55, in inner
    response = get_response(request)
  File "D:\Project\Django\.venv\lib\site-packages\django\core\handlers\base.py", line 197, in _get_response
    response = wrapped_callback(request, *callback_args, **callback_kwargs)
  File "D:\Project\Django\mysite\GIRng\views.py", line 48, in team
    return render(request, 'GIRng/team.html', {'form': form})
  File "D:\Project\Django\.venv\lib\site-packages\django\shortcuts.py", line 24, in render
    content = loader.render_to_string(template_name, context, request, using=using)
  File "D:\Project\Django\.venv\lib\site-packages\django\template\loader.py", line 62, in render_to_string
    return template.render(context, request)
  File "D:\Project\Django\.venv\lib\site-packages\django\template\backends\django.py", line 64, in render
    reraise(exc, self.backend)
  File "D:\Project\Django\.venv\lib\site-packages\django\template\backends\django.py", line 85, in reraise
    raise new from exc
django.template.exceptions.TemplateDoesNotExist: field_help_text_and_errors.html
D:\Project\Django\mysite\mysite\settings.py changed, reloading.
Watching for file changes with StatReloader
Internal Server Error: /girng/team
Traceback (most recent call last):
  File "D:\Project\Django\.venv\lib\site-packages\django\template\backends\django.py", line 62, in render
    return self.template.render(context)
  File "D:\Project\Django\.venv\lib\site-packages\django\template\base.py", line 175, in render
    return self._render(context)
  File "D:\Project\Django\.venv\lib\site-packages\django\template\base.py", line 167, in _render
    return self.nodelist.render(context)
  File "D:\Project\Django\.venv\lib\site-packages\django\template\base.py", line 1005, in render
    return SafeString("".join([node.render_annotated(context) for node in self]))
  File "D:\Project\Django\.venv\lib\site-packages\django\template\base.py", line 1005, in <listcomp>
    return SafeString("".join([node.render_annotated(context) for node in self]))
  File "D:\Project\Django\.venv\lib\site-packages\django\template\base.py", line 966, in render_annotated
    return self.render(context)
  File "D:\Project\Django\.venv\lib\site-packages\django\template\loader_tags.py", line 197, in render
    template = context.template.engine.select_template(template_name)
  File "D:\Project\Django\.venv\lib\site-packages\django\template\engine.py", line 212, in select_template
    raise TemplateDoesNotExist(", ".join(not_found))
django.template.exceptions.TemplateDoesNotExist: field_help_text_and_errors.html

The above exception was the direct cause of the following exception:

Traceback (most recent call last):
  File "D:\Project\Django\.venv\lib\site-packages\django\core\handlers\exception.py", line 55, in inner
    response = get_response(request)
  File "D:\Project\Django\.venv\lib\site-packages\django\core\handlers\base.py", line 197, in _get_response
    response = wrapped_callback(request, *callback_args, **callback_kwargs)
  File "D:\Project\Django\mysite\GIRng\views.py", line 48, in team
    return render(request, 'GIRng/team.html', {'form': form})
  File "D:\Project\Django\.venv\lib\site-packages\django\shortcuts.py", line 24, in render
    content = loader.render_to_string(template_name, context, request, using=using)
  File "D:\Project\Django\.venv\lib\site-packages\django\template\loader.py", line 62, in render_to_string
    return template.render(context, request)
  File "D:\Project\Django\.venv\lib\site-packages\django\template\backends\django.py", line 64, in render
    reraise(exc, self.backend)
  File "D:\Project\Django\.venv\lib\site-packages\django\template\backends\django.py", line 85, in reraise
    raise new from exc
django.template.exceptions.TemplateDoesNotExist: field_help_text_and_errors.html
Internal Server Error: /girng/team
Traceback (most recent call last):
  File "D:\Project\Django\.venv\lib\site-packages\django\template\backends\django.py", line 62, in render
    return self.template.render(context)
  File "D:\Project\Django\.venv\lib\site-packages\django\template\base.py", line 175, in render
    return self._render(context)
  File "D:\Project\Django\.venv\lib\site-packages\django\template\base.py", line 167, in _render
    return self.nodelist.render(context)
  File "D:\Project\Django\.venv\lib\site-packages\django\template\base.py", line 1005, in render
    return SafeString("".join([node.render_annotated(context) for node in self]))
  File "D:\Project\Django\.venv\lib\site-packages\django\template\base.py", line 1005, in <listcomp>
    return SafeString("".join([node.render_annotated(context) for node in self]))
  File "D:\Project\Django\.venv\lib\site-packages\django\template\base.py", line 966, in render_annotated
    return self.render(context)
  File "D:\Project\Django\.venv\lib\site-packages\django\template\loader_tags.py", line 197, in render
    template = context.template.engine.select_template(template_name)
  File "D:\Project\Django\.venv\lib\site-packages\django\template\engine.py", line 212, in select_template
    raise TemplateDoesNotExist(", ".join(not_found))
django.template.exceptions.TemplateDoesNotExist: bootstrap5:field_help_text_and_errors.html

The above exception was the direct cause of the following exception:

Traceback (most recent call last):
  File "D:\Project\Django\.venv\lib\site-packages\django\core\handlers\exception.py", line 55, in inner
    response = get_response(request)
  File "D:\Project\Django\.venv\lib\site-packages\django\core\handlers\base.py", line 197, in _get_response
    response = wrapped_callback(request, *callback_args, **callback_kwargs)
  File "D:\Project\Django\mysite\GIRng\views.py", line 48, in team
    return render(request, 'GIRng/team.html', {'form': form})
  File "D:\Project\Django\.venv\lib\site-packages\django\shortcuts.py", line 24, in render
    content = loader.render_to_string(template_name, context, request, using=using)
  File "D:\Project\Django\.venv\lib\site-packages\django\template\loader.py", line 62, in render_to_string
    return template.render(context, request)
  File "D:\Project\Django\.venv\lib\site-packages\django\template\backends\django.py", line 64, in render
    reraise(exc, self.backend)
  File "D:\Project\Django\.venv\lib\site-packages\django\template\backends\django.py", line 85, in reraise
    raise new from exc
django.template.exceptions.TemplateDoesNotExist: bootstrap5:field_help_text_and_errors.html
Internal Server Error: /girng/team
Traceback (most recent call last):
  File "D:\Project\Django\.venv\lib\site-packages\django\template\backends\django.py", line 62, in render
    return self.template.render(context)
  File "D:\Project\Django\.venv\lib\site-packages\django\template\base.py", line 175, in render
    return self._render(context)
  File "D:\Project\Django\.venv\lib\site-packages\django\template\base.py", line 167, in _render
    return self.nodelist.render(context)
  File "D:\Project\Django\.venv\lib\site-packages\django\template\base.py", line 1005, in render
    return SafeString("".join([node.render_annotated(context) for node in self]))
  File "D:\Project\Django\.venv\lib\site-packages\django\template\base.py", line 1005, in <listcomp>
    return SafeString("".join([node.render_annotated(context) for node in self]))
  File "D:\Project\Django\.venv\lib\site-packages\django\template\base.py", line 966, in render_annotated
    return self.render(context)
  File "D:\Project\Django\.venv\lib\site-packages\django\template\loader_tags.py", line 197, in render
    template = context.template.engine.select_template(template_name)
  File "D:\Project\Django\.venv\lib\site-packages\django\template\engine.py", line 212, in select_template
    raise TemplateDoesNotExist(", ".join(not_found))
django.template.exceptions.TemplateDoesNotExist: team_list.html

The above exception was the direct cause of the following exception:

Traceback (most recent call last):
  File "D:\Project\Django\.venv\lib\site-packages\django\core\handlers\exception.py", line 55, in inner
    response = get_response(request)
  File "D:\Project\Django\.venv\lib\site-packages\django\core\handlers\base.py", line 197, in _get_response
    response = wrapped_callback(request, *callback_args, **callback_kwargs)
  File "D:\Project\Django\mysite\GIRng\views.py", line 48, in team
    return render(request, 'GIRng/team.html', {'form': form})
  File "D:\Project\Django\.venv\lib\site-packages\django\shortcuts.py", line 24, in render
    content = loader.render_to_string(template_name, context, request, using=using)
  File "D:\Project\Django\.venv\lib\site-packages\django\template\loader.py", line 62, in render_to_string
    return template.render(context, request)
  File "D:\Project\Django\.venv\lib\site-packages\django\template\backends\django.py", line 64, in render
    reraise(exc, self.backend)
  File "D:\Project\Django\.venv\lib\site-packages\django\template\backends\django.py", line 85, in reraise
    raise new from exc
django.template.exceptions.TemplateDoesNotExist: team_list.html
Internal Server Error: /girng/team
Traceback (most recent call last):
  File "D:\Project\Django\.venv\lib\site-packages\django\template\backends\django.py", line 62, in render
    return self.template.render(context)
  File "D:\Project\Django\.venv\lib\site-packages\django\template\base.py", line 175, in render
    return self._render(context)
  File "D:\Project\Django\.venv\lib\site-packages\django\template\base.py", line 167, in _render
    return self.nodelist.render(context)
  File "D:\Project\Django\.venv\lib\site-packages\django\template\base.py", line 1005, in render
    return SafeString("".join([node.render_annotated(context) for node in self]))
  File "D:\Project\Django\.venv\lib\site-packages\django\template\base.py", line 1005, in <listcomp>
    return SafeString("".join([node.render_annotated(context) for node in self]))
  File "D:\Project\Django\.venv\lib\site-packages\django\template\base.py", line 966, in render_annotated
    return self.render(context)
  File "D:\Project\Django\.venv\lib\site-packages\django\template\loader_tags.py", line 197, in render
    template = context.template.engine.select_template(template_name)
  File "D:\Project\Django\.venv\lib\site-packages\django\template\engine.py", line 212, in select_template
    raise TemplateDoesNotExist(", ".join(not_found))
django.template.exceptions.TemplateDoesNotExist: GIRng:team_list.html

The above exception was the direct cause of the following exception:

Traceback (most recent call last):
  File "D:\Project\Django\.venv\lib\site-packages\django\core\handlers\exception.py", line 55, in inner
    response = get_response(request)
  File "D:\Project\Django\.venv\lib\site-packages\django\core\handlers\base.py", line 197, in _get_response
    response = wrapped_callback(request, *callback_args, **callback_kwargs)
  File "D:\Project\Django\mysite\GIRng\views.py", line 48, in team
    return render(request, 'GIRng/team.html', {'form': form})
  File "D:\Project\Django\.venv\lib\site-packages\django\shortcuts.py", line 24, in render
    content = loader.render_to_string(template_name, context, request, using=using)
  File "D:\Project\Django\.venv\lib\site-packages\django\template\loader.py", line 62, in render_to_string
    return template.render(context, request)
  File "D:\Project\Django\.venv\lib\site-packages\django\template\backends\django.py", line 64, in render
    reraise(exc, self.backend)
  File "D:\Project\Django\.venv\lib\site-packages\django\template\backends\django.py", line 85, in reraise
    raise new from exc
django.template.exceptions.TemplateDoesNotExist: GIRng:team_list.html
Internal Server Error: /girng/team
Traceback (most recent call last):
  File "D:\Project\Django\.venv\lib\site-packages\django\template\backends\django.py", line 62, in render
    return self.template.render(context)
  File "D:\Project\Django\.venv\lib\site-packages\django\template\base.py", line 175, in render
    return self._render(context)
  File "D:\Project\Django\.venv\lib\site-packages\django\template\base.py", line 167, in _render
    return self.nodelist.render(context)
  File "D:\Project\Django\.venv\lib\site-packages\django\template\base.py", line 1005, in render
    return SafeString("".join([node.render_annotated(context) for node in self]))
  File "D:\Project\Django\.venv\lib\site-packages\django\template\base.py", line 1005, in <listcomp>
    return SafeString("".join([node.render_annotated(context) for node in self]))
  File "D:\Project\Django\.venv\lib\site-packages\django\template\base.py", line 966, in render_annotated
    return self.render(context)
  File "D:\Project\Django\.venv\lib\site-packages\django\template\loader_tags.py", line 197, in render
    template = context.template.engine.select_template(template_name)
  File "D:\Project\Django\.venv\lib\site-packages\django\template\engine.py", line 212, in select_template
    raise TemplateDoesNotExist(", ".join(not_found))
django.template.exceptions.TemplateDoesNotExist: GIRng.team_list.html

The above exception was the direct cause of the following exception:

Traceback (most recent call last):
  File "D:\Project\Django\.venv\lib\site-packages\django\core\handlers\exception.py", line 55, in inner
    response = get_response(request)
  File "D:\Project\Django\.venv\lib\site-packages\django\core\handlers\base.py", line 197, in _get_response
    response = wrapped_callback(request, *callback_args, **callback_kwargs)
  File "D:\Project\Django\mysite\GIRng\views.py", line 48, in team
    return render(request, 'GIRng/team.html', {'form': form})
  File "D:\Project\Django\.venv\lib\site-packages\django\shortcuts.py", line 24, in render
    content = loader.render_to_string(template_name, context, request, using=using)
  File "D:\Project\Django\.venv\lib\site-packages\django\template\loader.py", line 62, in render_to_string
    return template.render(context, request)
  File "D:\Project\Django\.venv\lib\site-packages\django\template\backends\django.py", line 64, in render
    reraise(exc, self.backend)
  File "D:\Project\Django\.venv\lib\site-packages\django\template\backends\django.py", line 85, in reraise
    raise new from exc
django.template.exceptions.TemplateDoesNotExist: GIRng.team_list.html
Internal Server Error: /girng/team
Traceback (most recent call last):
  File "D:\Project\Django\.venv\lib\site-packages\django\template\backends\django.py", line 62, in render
    return self.template.render(context)
  File "D:\Project\Django\.venv\lib\site-packages\django\template\base.py", line 175, in render
    return self._render(context)
  File "D:\Project\Django\.venv\lib\site-packages\django\template\base.py", line 167, in _render
    return self.nodelist.render(context)
  File "D:\Project\Django\.venv\lib\site-packages\django\template\base.py", line 1005, in render
    return SafeString("".join([node.render_annotated(context) for node in self]))
  File "D:\Project\Django\.venv\lib\site-packages\django\template\base.py", line 1005, in <listcomp>
    return SafeString("".join([node.render_annotated(context) for node in self]))
  File "D:\Project\Django\.venv\lib\site-packages\django\template\base.py", line 966, in render_annotated
    return self.render(context)
  File "D:\Project\Django\.venv\lib\site-packages\django\template\loader_tags.py", line 197, in render
    template = context.template.engine.select_template(template_name)
  File "D:\Project\Django\.venv\lib\site-packages\django\template\engine.py", line 212, in select_template
    raise TemplateDoesNotExist(", ".join(not_found))
django.template.exceptions.TemplateDoesNotExist: GIRng/field_help_text_and_errors.html

The above exception was the direct cause of the following exception:

Traceback (most recent call last):
  File "D:\Project\Django\.venv\lib\site-packages\django\core\handlers\exception.py", line 55, in inner
    response = get_response(request)
  File "D:\Project\Django\.venv\lib\site-packages\django\core\handlers\base.py", line 197, in _get_response
    response = wrapped_callback(request, *callback_args, **callback_kwargs)
  File "D:\Project\Django\mysite\GIRng\views.py", line 48, in team
    return render(request, 'GIRng/team.html', {'form': form})
  File "D:\Project\Django\.venv\lib\site-packages\django\shortcuts.py", line 24, in render
    content = loader.render_to_string(template_name, context, request, using=using)
  File "D:\Project\Django\.venv\lib\site-packages\django\template\loader.py", line 62, in render_to_string
    return template.render(context, request)
  File "D:\Project\Django\.venv\lib\site-packages\django\template\backends\django.py", line 64, in render
    reraise(exc, self.backend)
  File "D:\Project\Django\.venv\lib\site-packages\django\template\backends\django.py", line 85, in reraise
    raise new from exc
django.template.exceptions.TemplateDoesNotExist: GIRng/field_help_text_and_errors.html
Internal Server Error: /girng/team
Traceback (most recent call last):
  File "D:\Project\Django\.venv\lib\site-packages\django\template\backends\django.py", line 62, in render
    return self.template.render(context)
  File "D:\Project\Django\.venv\lib\site-packages\django\template\base.py", line 175, in render
    return self._render(context)
  File "D:\Project\Django\.venv\lib\site-packages\django\template\base.py", line 167, in _render
    return self.nodelist.render(context)
  File "D:\Project\Django\.venv\lib\site-packages\django\template\base.py", line 1005, in render
    return SafeString("".join([node.render_annotated(context) for node in self]))
  File "D:\Project\Django\.venv\lib\site-packages\django\template\base.py", line 1005, in <listcomp>
    return SafeString("".join([node.render_annotated(context) for node in self]))
  File "D:\Project\Django\.venv\lib\site-packages\django\template\base.py", line 966, in render_annotated
    return self.render(context)
  File "D:\Project\Django\.venv\lib\site-packages\django\template\loader_tags.py", line 197, in render
    template = context.template.engine.select_template(template_name)
  File "D:\Project\Django\.venv\lib\site-packages\django\template\engine.py", line 212, in select_template
    raise TemplateDoesNotExist(", ".join(not_found))
django.template.exceptions.TemplateDoesNotExist: /polls/detail.html

The above exception was the direct cause of the following exception:

Traceback (most recent call last):
  File "D:\Project\Django\.venv\lib\site-packages\django\core\handlers\exception.py", line 55, in inner
    response = get_response(request)
  File "D:\Project\Django\.venv\lib\site-packages\django\core\handlers\base.py", line 197, in _get_response
    response = wrapped_callback(request, *callback_args, **callback_kwargs)
  File "D:\Project\Django\mysite\GIRng\views.py", line 48, in team
    return render(request, 'GIRng/team.html', {'form': form})
  File "D:\Project\Django\.venv\lib\site-packages\django\shortcuts.py", line 24, in render
    content = loader.render_to_string(template_name, context, request, using=using)
  File "D:\Project\Django\.venv\lib\site-packages\django\template\loader.py", line 62, in render_to_string
    return template.render(context, request)
  File "D:\Project\Django\.venv\lib\site-packages\django\template\backends\django.py", line 64, in render
    reraise(exc, self.backend)
  File "D:\Project\Django\.venv\lib\site-packages\django\template\backends\django.py", line 85, in reraise
    raise new from exc
django.template.exceptions.TemplateDoesNotExist: /polls/detail.html
Internal Server Error: /girng/team
Traceback (most recent call last):
  File "D:\Project\Django\.venv\lib\site-packages\django\template\backends\django.py", line 62, in render
    return self.template.render(context)
  File "D:\Project\Django\.venv\lib\site-packages\django\template\base.py", line 175, in render
    return self._render(context)
  File "D:\Project\Django\.venv\lib\site-packages\django\template\base.py", line 167, in _render
    return self.nodelist.render(context)
  File "D:\Project\Django\.venv\lib\site-packages\django\template\base.py", line 1005, in render
    return SafeString("".join([node.render_annotated(context) for node in self]))
  File "D:\Project\Django\.venv\lib\site-packages\django\template\base.py", line 1005, in <listcomp>
    return SafeString("".join([node.render_annotated(context) for node in self]))
  File "D:\Project\Django\.venv\lib\site-packages\django\template\base.py", line 966, in render_annotated
    return self.render(context)
  File "D:\Project\Django\.venv\lib\site-packages\django\template\loader_tags.py", line 197, in render
    template = context.template.engine.select_template(template_name)
  File "D:\Project\Django\.venv\lib\site-packages\django\template\engine.py", line 212, in select_template
    raise TemplateDoesNotExist(", ".join(not_found))
django.template.exceptions.TemplateDoesNotExist: mysite\polls\templates\polls

The above exception was the direct cause of the following exception:

Traceback (most recent call last):
  File "D:\Project\Django\.venv\lib\site-packages\django\core\handlers\exception.py", line 55, in inner
    response = get_response(request)
  File "D:\Project\Django\.venv\lib\site-packages\django\core\handlers\base.py", line 197, in _get_response
    response = wrapped_callback(request, *callback_args, **callback_kwargs)
  File "D:\Project\Django\mysite\GIRng\views.py", line 48, in team
    return render(request, 'GIRng/team.html', {'form': form})
  File "D:\Project\Django\.venv\lib\site-packages\django\shortcuts.py", line 24, in render
    content = loader.render_to_string(template_name, context, request, using=using)
  File "D:\Project\Django\.venv\lib\site-packages\django\template\loader.py", line 62, in render_to_string
    return template.render(context, request)
  File "D:\Project\Django\.venv\lib\site-packages\django\template\backends\django.py", line 64, in render
    reraise(exc, self.backend)
  File "D:\Project\Django\.venv\lib\site-packages\django\template\backends\django.py", line 85, in reraise
    raise new from exc
django.template.exceptions.TemplateDoesNotExist: mysite\polls\templates\polls
Internal Server Error: /girng/team
Traceback (most recent call last):
  File "D:\Project\Django\.venv\lib\site-packages\django\template\backends\django.py", line 62, in render
    return self.template.render(context)
  File "D:\Project\Django\.venv\lib\site-packages\django\template\base.py", line 175, in render
    return self._render(context)
  File "D:\Project\Django\.venv\lib\site-packages\django\template\base.py", line 167, in _render
    return self.nodelist.render(context)
  File "D:\Project\Django\.venv\lib\site-packages\django\template\base.py", line 1005, in render
    return SafeString("".join([node.render_annotated(context) for node in self]))
  File "D:\Project\Django\.venv\lib\site-packages\django\template\base.py", line 1005, in <listcomp>
    return SafeString("".join([node.render_annotated(context) for node in self]))
  File "D:\Project\Django\.venv\lib\site-packages\django\template\base.py", line 966, in render_annotated
    return self.render(context)
  File "D:\Project\Django\.venv\lib\site-packages\django\template\loader_tags.py", line 197, in render
    template = context.template.engine.select_template(template_name)
  File "D:\Project\Django\.venv\lib\site-packages\django\template\engine.py", line 212, in select_template
    raise TemplateDoesNotExist(", ".join(not_found))
django.template.exceptions.TemplateDoesNotExist: mysite/polls/templates/polls

The above exception was the direct cause of the following exception:

Traceback (most recent call last):
  File "D:\Project\Django\.venv\lib\site-packages\django\core\handlers\exception.py", line 55, in inner
    response = get_response(request)
  File "D:\Project\Django\.venv\lib\site-packages\django\core\handlers\base.py", line 197, in _get_response
    response = wrapped_callback(request, *callback_args, **callback_kwargs)
  File "D:\Project\Django\mysite\GIRng\views.py", line 48, in team
    return render(request, 'GIRng/team.html', {'form': form})
  File "D:\Project\Django\.venv\lib\site-packages\django\shortcuts.py", line 24, in render
    content = loader.render_to_string(template_name, context, request, using=using)
  File "D:\Project\Django\.venv\lib\site-packages\django\template\loader.py", line 62, in render_to_string
    return template.render(context, request)
  File "D:\Project\Django\.venv\lib\site-packages\django\template\backends\django.py", line 64, in render
    reraise(exc, self.backend)
  File "D:\Project\Django\.venv\lib\site-packages\django\template\backends\django.py", line 85, in reraise
    raise new from exc
django.template.exceptions.TemplateDoesNotExist: mysite/polls/templates/polls
Internal Server Error: /girng/team
Traceback (most recent call last):
  File "D:\Project\Django\.venv\lib\site-packages\django\core\handlers\exception.py", line 55, in inner
    response = get_response(request)
  File "D:\Project\Django\.venv\lib\site-packages\django\core\handlers\base.py", line 197, in _get_response
    response = wrapped_callback(request, *callback_args, **callback_kwargs)
  File "D:\Project\Django\mysite\GIRng\views.py", line 48, in team
    return render(request, 'GIRng/team.html', {'form': form})
  File "D:\Project\Django\.venv\lib\site-packages\django\shortcuts.py", line 24, in render
    content = loader.render_to_string(template_name, context, request, using=using)
  File "D:\Project\Django\.venv\lib\site-packages\django\template\loader.py", line 62, in render_to_string
    return template.render(context, request)
  File "D:\Project\Django\.venv\lib\site-packages\django\template\backends\django.py", line 62, in render
    return self.template.render(context)
  File "D:\Project\Django\.venv\lib\site-packages\django\template\base.py", line 175, in render
    return self._render(context)
  File "D:\Project\Django\.venv\lib\site-packages\django\template\base.py", line 167, in _render
    return self.nodelist.render(context)
  File "D:\Project\Django\.venv\lib\site-packages\django\template\base.py", line 1005, in render
    return SafeString("".join([node.render_annotated(context) for node in self]))
  File "D:\Project\Django\.venv\lib\site-packages\django\template\base.py", line 1005, in <listcomp>
    return SafeString("".join([node.render_annotated(context) for node in self]))
  File "D:\Project\Django\.venv\lib\site-packages\django\template\base.py", line 966, in render_annotated
    return self.render(context)
  File "D:\Project\Django\.venv\lib\site-packages\django\template\loader_tags.py", line 208, in render
    return template.render(context)
  File "D:\Project\Django\.venv\lib\site-packages\django\template\base.py", line 177, in render
    return self._render(context)
  File "D:\Project\Django\.venv\lib\site-packages\django\template\base.py", line 167, in _render
    return self.nodelist.render(context)
  File "D:\Project\Django\.venv\lib\site-packages\django\template\base.py", line 1005, in render
    return SafeString("".join([node.render_annotated(context) for node in self]))
  File "D:\Project\Django\.venv\lib\site-packages\django\template\base.py", line 1005, in <listcomp>
    return SafeString("".join([node.render_annotated(context) for node in self]))
  File "D:\Project\Django\.venv\lib\site-packages\django\template\base.py", line 966, in render_annotated
    return self.render(context)
  File "D:\Project\Django\.venv\lib\site-packages\django\template\defaulttags.py", line 472, in render
    url = reverse(view_name, args=args, kwargs=kwargs, current_app=current_app)
  File "D:\Project\Django\.venv\lib\site-packages\django\urls\base.py", line 88, in reverse
    return resolver._reverse_with_prefix(view, prefix, *args, **kwargs)
  File "D:\Project\Django\.venv\lib\site-packages\django\urls\resolvers.py", line 828, in _reverse_with_prefix
    raise NoReverseMatch(msg)
django.urls.exceptions.NoReverseMatch: Reverse for 'vote' with arguments '('',)' not found. 1 pattern(s) tried: ['polls/(?P<question_id>[0-9]+)/vote/\\Z']
Internal Server Error: /girng/team
Traceback (most recent call last):
  File "D:\Project\Django\.venv\lib\site-packages\django\template\backends\django.py", line 62, in render
    return self.template.render(context)
  File "D:\Project\Django\.venv\lib\site-packages\django\template\base.py", line 175, in render
    return self._render(context)
  File "D:\Project\Django\.venv\lib\site-packages\django\template\base.py", line 167, in _render
    return self.nodelist.render(context)
  File "D:\Project\Django\.venv\lib\site-packages\django\template\base.py", line 1005, in render
    return SafeString("".join([node.render_annotated(context) for node in self]))
  File "D:\Project\Django\.venv\lib\site-packages\django\template\base.py", line 1005, in <listcomp>
    return SafeString("".join([node.render_annotated(context) for node in self]))
  File "D:\Project\Django\.venv\lib\site-packages\django\template\base.py", line 966, in render_annotated
    return self.render(context)
  File "D:\Project\Django\.venv\lib\site-packages\django\template\loader_tags.py", line 197, in render
    template = context.template.engine.select_template(template_name)
  File "D:\Project\Django\.venv\lib\site-packages\django\template\engine.py", line 212, in select_template
    raise TemplateDoesNotExist(", ".join(not_found))
django.template.exceptions.TemplateDoesNotExist: mysite/polls/templates/polls/index.html

The above exception was the direct cause of the following exception:

Traceback (most recent call last):
  File "D:\Project\Django\.venv\lib\site-packages\django\core\handlers\exception.py", line 55, in inner
    response = get_response(request)
  File "D:\Project\Django\.venv\lib\site-packages\django\core\handlers\base.py", line 197, in _get_response
    response = wrapped_callback(request, *callback_args, **callback_kwargs)
  File "D:\Project\Django\mysite\GIRng\views.py", line 48, in team
    return render(request, 'GIRng/team.html', {'form': form})
  File "D:\Project\Django\.venv\lib\site-packages\django\shortcuts.py", line 24, in render
    content = loader.render_to_string(template_name, context, request, using=using)
  File "D:\Project\Django\.venv\lib\site-packages\django\template\loader.py", line 62, in render_to_string
    return template.render(context, request)
  File "D:\Project\Django\.venv\lib\site-packages\django\template\backends\django.py", line 64, in render
    reraise(exc, self.backend)
  File "D:\Project\Django\.venv\lib\site-packages\django\template\backends\django.py", line 85, in reraise
    raise new from exc
django.template.exceptions.TemplateDoesNotExist: mysite/polls/templates/polls/index.html
Watching for file changes with StatReloader
Watching for file changes with StatReloader
Not Found: /favicon.ico
Not Found: /girng//
This is logger: xdding
Internal Server Error: /girng/randomize
Traceback (most recent call last):
  File "D:\Project\Django\.venv\lib\site-packages\django\db\backends\utils.py", line 89, in _execute
    return self.cursor.execute(sql, params)
  File "D:\Project\Django\.venv\lib\site-packages\django\db\backends\mysql\base.py", line 75, in execute
    return self.cursor.execute(query, args)
  File "D:\Project\Django\.venv\lib\site-packages\MySQLdb\cursors.py", line 206, in execute
    res = self._query(query)
  File "D:\Project\Django\.venv\lib\site-packages\MySQLdb\cursors.py", line 319, in _query
    db.query(q)
  File "D:\Project\Django\.venv\lib\site-packages\MySQLdb\connections.py", line 254, in query
    _mysql.connection.query(self, query)
MySQLdb.OperationalError: (1054, "Unknown column 'GIRng_character.description' in 'field list'")

The above exception was the direct cause of the following exception:

Traceback (most recent call last):
  File "D:\Project\Django\.venv\lib\site-packages\django\core\handlers\exception.py", line 55, in inner
    response = get_response(request)
  File "D:\Project\Django\.venv\lib\site-packages\django\core\handlers\base.py", line 197, in _get_response
    response = wrapped_callback(request, *callback_args, **callback_kwargs)
  File "D:\Project\Django\mysite\GIRng\views.py", line 79, in generate
    char_list = randomize()
  File "D:\Project\Django\mysite\GIRng\views.py", line 56, in randomize
    all_char = list(Character.objects.all())
  File "D:\Project\Django\.venv\lib\site-packages\django\db\models\query.py", line 394, in __iter__
    self._fetch_all()
  File "D:\Project\Django\.venv\lib\site-packages\django\db\models\query.py", line 1867, in _fetch_all
    self._result_cache = list(self._iterable_class(self))
  File "D:\Project\Django\.venv\lib\site-packages\django\db\models\query.py", line 87, in __iter__
    results = compiler.execute_sql(
  File "D:\Project\Django\.venv\lib\site-packages\django\db\models\sql\compiler.py", line 1398, in execute_sql
    cursor.execute(sql, params)
  File "D:\Project\Django\.venv\lib\site-packages\django\db\backends\utils.py", line 103, in execute
    return super().execute(sql, params)
  File "D:\Project\Django\.venv\lib\site-packages\django\db\backends\utils.py", line 67, in execute
    return self._execute_with_wrappers(
  File "D:\Project\Django\.venv\lib\site-packages\django\db\backends\utils.py", line 80, in _execute_with_wrappers
    return executor(sql, params, many, context)
  File "D:\Project\Django\.venv\lib\site-packages\django\db\backends\utils.py", line 84, in _execute
    with self.db.wrap_database_errors:
  File "D:\Project\Django\.venv\lib\site-packages\django\db\utils.py", line 91, in __exit__
    raise dj_exc_value.with_traceback(traceback) from exc_value
  File "D:\Project\Django\.venv\lib\site-packages\django\db\backends\utils.py", line 89, in _execute
    return self.cursor.execute(sql, params)
  File "D:\Project\Django\.venv\lib\site-packages\django\db\backends\mysql\base.py", line 75, in execute
    return self.cursor.execute(query, args)
  File "D:\Project\Django\.venv\lib\site-packages\MySQLdb\cursors.py", line 206, in execute
    res = self._query(query)
  File "D:\Project\Django\.venv\lib\site-packages\MySQLdb\cursors.py", line 319, in _query
    db.query(q)
  File "D:\Project\Django\.venv\lib\site-packages\MySQLdb\connections.py", line 254, in query
    _mysql.connection.query(self, query)
django.db.utils.OperationalError: (1054, "Unknown column 'GIRng_character.description' in 'field list'")
Internal Server Error: /girng/team
Traceback (most recent call last):
  File "D:\Project\Django\.venv\lib\site-packages\django\db\backends\utils.py", line 89, in _execute
    return self.cursor.execute(sql, params)
  File "D:\Project\Django\.venv\lib\site-packages\django\db\backends\mysql\base.py", line 75, in execute
    return self.cursor.execute(query, args)
  File "D:\Project\Django\.venv\lib\site-packages\MySQLdb\cursors.py", line 206, in execute
    res = self._query(query)
  File "D:\Project\Django\.venv\lib\site-packages\MySQLdb\cursors.py", line 319, in _query
    db.query(q)
  File "D:\Project\Django\.venv\lib\site-packages\MySQLdb\connections.py", line 254, in query
    _mysql.connection.query(self, query)
MySQLdb.OperationalError: (1054, "Unknown column 'GIRng_character.description' in 'field list'")

The above exception was the direct cause of the following exception:

Traceback (most recent call last):
  File "D:\Project\Django\.venv\lib\site-packages\django\core\handlers\exception.py", line 55, in inner
    response = get_response(request)
  File "D:\Project\Django\.venv\lib\site-packages\django\core\handlers\base.py", line 197, in _get_response
    response = wrapped_callback(request, *callback_args, **callback_kwargs)
  File "D:\Project\Django\mysite\GIRng\views.py", line 52, in team
    return render(request, 'GIRng/team.html', {'form': form})
  File "D:\Project\Django\.venv\lib\site-packages\django\shortcuts.py", line 24, in render
    content = loader.render_to_string(template_name, context, request, using=using)
  File "D:\Project\Django\.venv\lib\site-packages\django\template\loader.py", line 62, in render_to_string
    return template.render(context, request)
  File "D:\Project\Django\.venv\lib\site-packages\django\template\backends\django.py", line 62, in render
    return self.template.render(context)
  File "D:\Project\Django\.venv\lib\site-packages\django\template\base.py", line 175, in render
    return self._render(context)
  File "D:\Project\Django\.venv\lib\site-packages\django\template\base.py", line 167, in _render
    return self.nodelist.render(context)
  File "D:\Project\Django\.venv\lib\site-packages\django\template\base.py", line 1005, in render
    return SafeString("".join([node.render_annotated(context) for node in self]))
  File "D:\Project\Django\.venv\lib\site-packages\django\template\base.py", line 1005, in <listcomp>
    return SafeString("".join([node.render_annotated(context) for node in self]))
  File "D:\Project\Django\.venv\lib\site-packages\django\template\base.py", line 966, in render_annotated
    return self.render(context)
  File "D:\Project\Django\.venv\lib\site-packages\django\template\base.py", line 1070, in render
    return render_value_in_context(output, context)
  File "D:\Project\Django\.venv\lib\site-packages\django\template\base.py", line 1047, in render_value_in_context
    value = str(value)
  File "D:\Project\Django\.venv\lib\site-packages\django\utils\html.py", line 419, in <lambda>
    klass.__str__ = lambda self: mark_safe(klass_str(self))
  File "D:\Project\Django\.venv\lib\site-packages\django\forms\boundfield.py", line 34, in __str__
    return self.as_widget()
  File "D:\Project\Django\.venv\lib\site-packages\django\forms\boundfield.py", line 99, in as_widget
    return widget.render(
  File "D:\Project\Django\.venv\lib\site-packages\django\forms\widgets.py", line 280, in render
    context = self.get_context(name, value, attrs)
  File "D:\Project\Django\.venv\lib\site-packages\django\forms\widgets.py", line 693, in get_context
    context["widget"]["optgroups"] = self.optgroups(
  File "D:\Project\Django\.venv\lib\site-packages\django\forms\widgets.py", line 633, in optgroups
    for index, (option_value, option_label) in enumerate(self.choices):
  File "D:\Project\Django\.venv\lib\site-packages\django\forms\models.py", line 1409, in __iter__
    for obj in queryset:
  File "D:\Project\Django\.venv\lib\site-packages\django\db\models\query.py", line 512, in _iterator
    yield from iterable
  File "D:\Project\Django\.venv\lib\site-packages\django\db\models\query.py", line 87, in __iter__
    results = compiler.execute_sql(
  File "D:\Project\Django\.venv\lib\site-packages\django\db\models\sql\compiler.py", line 1398, in execute_sql
    cursor.execute(sql, params)
  File "D:\Project\Django\.venv\lib\site-packages\django\db\backends\utils.py", line 103, in execute
    return super().execute(sql, params)
  File "D:\Project\Django\.venv\lib\site-packages\django\db\backends\utils.py", line 67, in execute
    return self._execute_with_wrappers(
  File "D:\Project\Django\.venv\lib\site-packages\django\db\backends\utils.py", line 80, in _execute_with_wrappers
    return executor(sql, params, many, context)
  File "D:\Project\Django\.venv\lib\site-packages\django\db\backends\utils.py", line 84, in _execute
    with self.db.wrap_database_errors:
  File "D:\Project\Django\.venv\lib\site-packages\django\db\utils.py", line 91, in __exit__
    raise dj_exc_value.with_traceback(traceback) from exc_value
  File "D:\Project\Django\.venv\lib\site-packages\django\db\backends\utils.py", line 89, in _execute
    return self.cursor.execute(sql, params)
  File "D:\Project\Django\.venv\lib\site-packages\django\db\backends\mysql\base.py", line 75, in execute
    return self.cursor.execute(query, args)
  File "D:\Project\Django\.venv\lib\site-packages\MySQLdb\cursors.py", line 206, in execute
    res = self._query(query)
  File "D:\Project\Django\.venv\lib\site-packages\MySQLdb\cursors.py", line 319, in _query
    db.query(q)
  File "D:\Project\Django\.venv\lib\site-packages\MySQLdb\connections.py", line 254, in query
    _mysql.connection.query(self, query)
django.db.utils.OperationalError: (1054, "Unknown column 'GIRng_character.description' in 'field list'")
Internal Server Error: /girng/characters/
Traceback (most recent call last):
  File "D:\Project\Django\.venv\lib\site-packages\django\db\backends\utils.py", line 89, in _execute
    return self.cursor.execute(sql, params)
  File "D:\Project\Django\.venv\lib\site-packages\django\db\backends\mysql\base.py", line 75, in execute
    return self.cursor.execute(query, args)
  File "D:\Project\Django\.venv\lib\site-packages\MySQLdb\cursors.py", line 206, in execute
    res = self._query(query)
  File "D:\Project\Django\.venv\lib\site-packages\MySQLdb\cursors.py", line 319, in _query
    db.query(q)
  File "D:\Project\Django\.venv\lib\site-packages\MySQLdb\connections.py", line 254, in query
    _mysql.connection.query(self, query)
MySQLdb.OperationalError: (1054, "Unknown column 'GIRng_character.description' in 'field list'")

The above exception was the direct cause of the following exception:

Traceback (most recent call last):
  File "D:\Project\Django\.venv\lib\site-packages\django\core\handlers\exception.py", line 55, in inner
    response = get_response(request)
  File "D:\Project\Django\.venv\lib\site-packages\django\core\handlers\base.py", line 220, in _get_response
    response = response.render()
  File "D:\Project\Django\.venv\lib\site-packages\django\template\response.py", line 114, in render
    self.content = self.rendered_content
  File "D:\Project\Django\.venv\lib\site-packages\django\template\response.py", line 92, in rendered_content
    return template.render(context, self._request)
  File "D:\Project\Django\.venv\lib\site-packages\django\template\backends\django.py", line 62, in render
    return self.template.render(context)
  File "D:\Project\Django\.venv\lib\site-packages\django\template\base.py", line 175, in render
    return self._render(context)
  File "D:\Project\Django\.venv\lib\site-packages\django\template\base.py", line 167, in _render
    return self.nodelist.render(context)
  File "D:\Project\Django\.venv\lib\site-packages\django\template\base.py", line 1005, in render
    return SafeString("".join([node.render_annotated(context) for node in self]))
  File "D:\Project\Django\.venv\lib\site-packages\django\template\base.py", line 1005, in <listcomp>
    return SafeString("".join([node.render_annotated(context) for node in self]))
  File "D:\Project\Django\.venv\lib\site-packages\django\template\base.py", line 966, in render_annotated
    return self.render(context)
  File "D:\Project\Django\.venv\lib\site-packages\django\template\loader_tags.py", line 54, in render
    result = self.nodelist.render(context)
  File "D:\Project\Django\.venv\lib\site-packages\django\template\base.py", line 1005, in render
    return SafeString("".join([node.render_annotated(context) for node in self]))
  File "D:\Project\Django\.venv\lib\site-packages\django\template\base.py", line 1005, in <listcomp>
    return SafeString("".join([node.render_annotated(context) for node in self]))
  File "D:\Project\Django\.venv\lib\site-packages\django\template\base.py", line 966, in render_annotated
    return self.render(context)
  File "D:\Project\Django\.venv\lib\site-packages\django\template\defaulttags.py", line 194, in render
    len_values = len(values)
  File "D:\Project\Django\.venv\lib\site-packages\django\db\models\query.py", line 376, in __len__
    self._fetch_all()
  File "D:\Project\Django\.venv\lib\site-packages\django\db\models\query.py", line 1867, in _fetch_all
    self._result_cache = list(self._iterable_class(self))
  File "D:\Project\Django\.venv\lib\site-packages\django\db\models\query.py", line 87, in __iter__
    results = compiler.execute_sql(
  File "D:\Project\Django\.venv\lib\site-packages\django\db\models\sql\compiler.py", line 1398, in execute_sql
    cursor.execute(sql, params)
  File "D:\Project\Django\.venv\lib\site-packages\django\db\backends\utils.py", line 103, in execute
    return super().execute(sql, params)
  File "D:\Project\Django\.venv\lib\site-packages\django\db\backends\utils.py", line 67, in execute
    return self._execute_with_wrappers(
  File "D:\Project\Django\.venv\lib\site-packages\django\db\backends\utils.py", line 80, in _execute_with_wrappers
    return executor(sql, params, many, context)
  File "D:\Project\Django\.venv\lib\site-packages\django\db\backends\utils.py", line 84, in _execute
    with self.db.wrap_database_errors:
  File "D:\Project\Django\.venv\lib\site-packages\django\db\utils.py", line 91, in __exit__
    raise dj_exc_value.with_traceback(traceback) from exc_value
  File "D:\Project\Django\.venv\lib\site-packages\django\db\backends\utils.py", line 89, in _execute
    return self.cursor.execute(sql, params)
  File "D:\Project\Django\.venv\lib\site-packages\django\db\backends\mysql\base.py", line 75, in execute
    return self.cursor.execute(query, args)
  File "D:\Project\Django\.venv\lib\site-packages\MySQLdb\cursors.py", line 206, in execute
    res = self._query(query)
  File "D:\Project\Django\.venv\lib\site-packages\MySQLdb\cursors.py", line 319, in _query
    db.query(q)
  File "D:\Project\Django\.venv\lib\site-packages\MySQLdb\connections.py", line 254, in query
    _mysql.connection.query(self, query)
django.db.utils.OperationalError: (1054, "Unknown column 'GIRng_character.description' in 'field list'")
Watching for file changes with StatReloader
Watching for file changes with StatReloader
Watching for file changes with StatReloader
Not Found: /
This is logger: xdding
Watching for file changes with StatReloader
Not Found: /girng/teamlist/
Not Found: /girng/teamlist/
Not Found: /girng/teamlist/
Not Found: /girng/team-list/
Not Found: /girng/teamlist/
Not Found: /girng/teamlist/
Watching for file changes with StatReloader
This is logger: xdding
Not Found: /favicon.ico
D:\Project\Django\mysite\GIRng\views.py changed, reloading.
Watching for file changes with StatReloader
Logging: This is index
Watching for file changes with StatReloader
D:\Project\Django\mysite\GIRng\urls.py changed, reloading.
Watching for file changes with StatReloader
D:\Project\Django\mysite\GIRng\urls.py changed, reloading.
Watching for file changes with StatReloader
D:\Project\Django\mysite\GIRng\urls.py changed, reloading.
Watching for file changes with StatReloader
Logging: This is index
Not Found: /favicon.ico
Watching for file changes with StatReloader
Logging: This is index
Internal Server Error: /girng/
Traceback (most recent call last):
  File "D:\Project\Django\.venv\lib\site-packages\django\core\handlers\exception.py", line 55, in inner
    response = get_response(request)
  File "D:\Project\Django\.venv\lib\site-packages\django\core\handlers\base.py", line 197, in _get_response
    response = wrapped_callback(request, *callback_args, **callback_kwargs)
  File "D:\Project\Django\.venv\lib\site-packages\django\contrib\auth\decorators.py", line 23, in _wrapped_view
    return view_func(request, *args, **kwargs)
  File "D:\Project\Django\mysite\GIRng\views.py", line 27, in index
    return render(request, 'GIRng/index.html')
  File "D:\Project\Django\.venv\lib\site-packages\django\shortcuts.py", line 24, in render
    content = loader.render_to_string(template_name, context, request, using=using)
  File "D:\Project\Django\.venv\lib\site-packages\django\template\loader.py", line 62, in render_to_string
    return template.render(context, request)
  File "D:\Project\Django\.venv\lib\site-packages\django\template\backends\django.py", line 62, in render
    return self.template.render(context)
  File "D:\Project\Django\.venv\lib\site-packages\django\template\base.py", line 175, in render
    return self._render(context)
  File "D:\Project\Django\.venv\lib\site-packages\django\template\base.py", line 167, in _render
    return self.nodelist.render(context)
  File "D:\Project\Django\.venv\lib\site-packages\django\template\base.py", line 1005, in render
    return SafeString("".join([node.render_annotated(context) for node in self]))
  File "D:\Project\Django\.venv\lib\site-packages\django\template\base.py", line 1005, in <listcomp>
    return SafeString("".join([node.render_annotated(context) for node in self]))
  File "D:\Project\Django\.venv\lib\site-packages\django\template\base.py", line 966, in render_annotated
    return self.render(context)
  File "D:\Project\Django\.venv\lib\site-packages\django\template\defaulttags.py", line 472, in render
    url = reverse(view_name, args=args, kwargs=kwargs, current_app=current_app)
  File "D:\Project\Django\.venv\lib\site-packages\django\urls\base.py", line 88, in reverse
    return resolver._reverse_with_prefix(view, prefix, *args, **kwargs)
  File "D:\Project\Django\.venv\lib\site-packages\django\urls\resolvers.py", line 828, in _reverse_with_prefix
    raise NoReverseMatch(msg)
django.urls.exceptions.NoReverseMatch: Reverse for 'team' not found. 'team' is not a valid view function or pattern name.
Not Found: /favicon.ico
Logging: This is index
Logging: This is index
D:\Project\Django\mysite\GIRng\models.py changed, reloading.
Watching for file changes with StatReloader
D:\Project\Django\mysite\GIRng\models.py changed, reloading.
Watching for file changes with StatReloader
D:\Project\Django\mysite\GIRng\urls.py changed, reloading.
Watching for file changes with StatReloader
